Workbook

Sheet 封面
A1: 中国建筑 项目管理表格
A2: 项目成本分析报告 | F2: 模板编号
F3: CSCECXJ-BM-M005
B5: 工程名称： | C5: XXX项目
B6: 工程地点： | C6: 龙岗区宝龙街道宝龙二路与高科大道交汇处西南侧
B7: 结构形式： | C7: 框架剪力墙结构
B8: 建筑面积： | C8: 45127.93m3
B9: 累计预算收入： | C9: =+汇总表!D21 -> 1.1111371e+08
B10: 累计责任成本： | C10: =+汇总表!E21 -> 1.1107911e+08
B11: 累计计划成本： | C11: =+C10 -> 1.1107911e+08
B12: 累计实际成本： | C12: =+汇总表!L21 -> 47000639
B13: 编 制 人： | C13: 朱雪晴
B14: 审 核 人： | C14: 胡凯
B15: 编制单位： | C15: XXX项目
B16: 编制日期： | C16: 45407

Sheet 填报说明
A1: 填报说明：
A2: 1、汇总表中数据是由14个分表组成（人工费、材料费、机械费、专业分包费、周转料具、安全文明施工费、施工措施费、现场经费、管理费利润规费税金、让利、总包服务费、指定分包（含税）、其它、开源效益）。信息化中的汇总表连接各相关分表，信息系统自动提取，不需填制。
A3: 2、13个分表三大列（预计工程竣工数据统计、本期数据统计、累计数据统计）中的收入、成本，简化列项，可仅列一行合计。其中人工费、专业分包费、机械费、周转料具、指定分包成本：可按分包队伍列项，涉及到安全文明施工费、施工措施费摘出来单列。
A4: 3、材料费中的主材分析，要与手册成本篇中成本控制主要目标的材料种类、物资篇主材耗量数据分析统计表相匹配，物资篇主材耗量数据分析统计表中采购数量、成本半成本数量、库存原材数量、废旧（待）处理数量、调入数量、调出数量由物资工程师提供，商务把对应的预算量提供给物资，这样主材分析完全一致；物资篇主材耗量数据分析统计表做为附件上传。
A5: 4、开源效益表必须按表格中的内容详细填写，并做为内审检查依据。
A6: 5、把两算相关的支撑资料、详细计算表格作为附件上传。
A7: 6、营改增后，对于新项目，收入成本均不含税，但业主应收款要录含税的，分包报量的应付款也是录含税的。
A8: 7、现场经费明细已完全与财务科目对应

Sheet 汇总表
A1: 工程项目“两算”对比分析汇总表
A2: 工程名称：XXX项目
A3: 序号 | B3: 费用名称 | C3: 单位 | D3: 预计工程竣工数据统计 | G3: 本期数据统计 | K3: 累计数据统计 | O3: 备注
D4: 预计总收入 | E4: 预计总成本 | F4: 差额（预计总收入-预计总成本） | G4: 预算收入 | H4: 实际成本 | I4: 差额（预算收入-实际成本） | J4: 节(+)超(-)(%) | K4: 预算收入 | L4: 实际成本 | M4: 差额（预算收入-实际成本） | N4: 节(+)超(-)(%)
A5: 1 | B5: 人工费 | C5: 元 | D5: =+人工费!G282 -> 6552396.2 | E5: =+人工费!J282 -> 7593488.5 | F5: =D5-E5 -> -1041092.2 | G5: =+人工费!M282 -> 343218.91 | H5: =+人工费!P282 -> 335618.08 | I5: =+G5-H5 -> 7600.8233 | J5: =I5/G5 -> 0.022145701 | K5: =+人工费!S282 -> 4279381.3 | L5: =+人工费!V282 -> 4368817.1 | M5: =+K5-L5 -> -89435.814 | N5: =M5/K5 -> -0.02089924
A6: 2 | B6: 材料费 | C6: 元 | D6: =+材料费!G283 -> 27372618 | E6: =+材料费!J283 -> 21407207 | F6: =D6-E6 -> 5965411 | G6: =+材料费!M283 -> 1142978.8 | H6: =+材料费!P283 -> 2726428.2 | I6: =+G6-H6 -> -1583449.4 | J6: =I6/G6 -> -1.3853707 | K6: =+材料费!S283 -> 19534317 | L6: =+材料费!V283 -> 16261971 | M6: =+K6-L6 -> 3272346.4 | N6: =M6/K6 -> 0.16751782
A7: 3 | B7: 机械费 | C7: 元 | D7: =+机械费!F26 -> 2908349.7 | E7: =+机械费!I26 -> 5310305.5 | F7: =D7-E7 -> -2401955.8 | G7: =+机械费!L26 -> 112946.82 | H7: =+机械费!P26 -> 317779.39 | I7: =+G7-H7 -> -204832.57 | J7: =I7/G7 -> -1.8135312 | K7: =+机械费!S26 -> 1292176.1 | L7: =+机械费!W26 -> 2222622.6 | M7: =+K7-L7 -> -930446.45 | N7: =M7/K7 -> -0.72006163
A8: 4 | B8: 专业分包费 | C8: 元 | D8: =+专业分包费!G582 -> 36605672 | E8: =+专业分包费!J582 -> 41376861 | F8: =D8-E8 -> -4771189 | G8: =+专业分包费!M582 -> -594003.69 | H8: =+专业分包费!P582 -> -51802.339 | I8: =+G8-H8 -> -542201.35 | J8: =I8/G8 -> 0.91279122 | K8: =+专业分包费!S582 -> 5450338.2 | L8: =+专业分包费!V582 -> 6581032.5 | M8: =+K8-L8 -> -1130694.3 | N8: =M8/K8 -> -0.20745397
A9: 5 | B9: 周转料具 | C9: 元 | D9: =+周转料具!G153 -> 14850944 | E9: =+周转料具!J153 -> 15189226 | F9: =D9-E9 -> -338282.24 | G9: =+周转料具!M153 -> 2428271.4 | H9: =+周转料具!P153 -> 881602.17 | I9: =+G9-H9 -> 1546669.2 | J9: =I9/G9 -> 0.63694249 | K9: =+周转料具!S153 -> 8875550.7 | L9: =+周转料具!V153 -> 7555071.6 | M9: =+K9-L9 -> 1320479 | N9: =M9/K9 -> 0.14877714
A10: 6 | B10: 安全文明施工费 | C10: 元 | D10: =+安全文明施工费!E36 -> 3721871.1 | E10: =+安全文明施工费!G36 -> 4196897.5 | F10: =D10-E10 -> -475026.44 | G10: =+安全文明施工费!I36 -> 144735.76 | H10: =+安全文明施工费!L36 -> 363412.05 | I10: =+G10-H10 -> -218676.29 | J10: =I10/G10 -> -1.5108656 | K10: =+安全文明施工费!N36 -> 1524999.2 | L10: =+安全文明施工费!Q36 -> 4162523.7 | M10: =+K10-L10 -> -2637524.5 | N10: =M10/K10 -> -1.7295252
A11: 7 | B11: 施工措施费 | C11: 元 | D11: 0 | E11: =+施工措施费!E22 -> 1656710 | F11: =D11-E11 -> -1656710 | G11: =+施工措施费!G22 -> 0 | H11: =+施工措施费!J22 -> 8867.93 | I11: =+G11-H11 -> -8867.93 | J11: =I11/G11 -> #DIV/0! | K11: =+施工措施费!L22 -> 0 | L11: =+施工措施费!O22 -> 1088344.4 | M11: =+K11-L11 -> -1088344.4 | N11: =M11/K11 -> #DIV/0!
A12: 8 | B12: 现场管理费 | C12: 元 | D12: =+'管理费、利润、规费、税金'!D5 -> 4884475.9 | E12: =+'管理费、利润、规费、税金'!E5 -> 13200702 | F12: =D12-E12 -> -8316226.5 | G12: =+'管理费、利润、规费、税金'!F5 -> 189947.03 | H12: =+'管理费、利润、规费、税金'!G5 -> -728996.59 | I12: =+G12-H12 -> 918943.62 | J12: =I12/G12 -> 4.8378941 | K12: =+'管理费、利润、规费、税金'!H5 -> 2001364.8 | L12: =+'管理费、利润、规费、税金'!I5 -> 4785734.2 | M12: =+K12-L12 -> -2784369.4 | N12: =M12/K12 -> -1.3912353
A13: 9 | B13: 利 润 | C13: 元 | D13: =+'管理费、利润、规费、税金'!D6 -> 4867994.6 | E13: 0 | F13: =D13-E13 -> 4867994.6 | G13: =+'管理费、利润、规费、税金'!F6 -> 189306.11 | H13: =+'管理费、利润、规费、税金'!G6 -> 0 | I13: =+G13-H13 -> 189306.11 | J13: =I13/G13 -> 1 | K13: =+'管理费、利润、规费、税金'!H6 -> 1994611.8 | L13: =+'管理费、利润、规费、税金'!I6 -> 0 | M13: =+K13-L13 -> 1994611.8 | N13: =M13/K13 -> 1
A14: 10 | B14: 规 费 | C14: 元 | D14: =+'管理费、利润、规费、税金'!D7 -> 5142966.4 | E14: 0 | F14: =D14-E14 -> 5142966.4 | G14: =+'管理费、利润、规费、税金'!F7 -> 199999.18 | H14: =+'管理费、利润、规费、税金'!G7 -> 0 | I14: =+G14-H14 -> 199999.18 | J14: =I14/G14 -> 1 | K14: =+'管理费、利润、规费、税金'!H7 -> 2107278.7 | L14: =+'管理费、利润、规费、税金'!I7 -> 0 | M14: =+K14-L14 -> 2107278.7 | N14: =M14/K14 -> 1
A15: 11 | B15: 税 金 | C15: 元 | D15: 0 | E15: 0 | F15: =D15-E15 -> 0 | G15: =+'管理费、利润、规费、税金'!F8 -> 0 | H15: =+'管理费、利润、规费、税金'!G8 -> 0 | I15: =+G15-H15 -> 0 | J15: =I15/G15 -> #DIV/0! | K15: =+'管理费、利润、规费、税金'!H8 -> 0 | L15: =+'管理费、利润、规费、税金'!I8 -> 0 | M15: =+K15-L15 -> 0 | N15: =M15/K15 -> #DIV/0!
A16: 12 | B16: 让 利 | C16: 元 | D16: 0 | E16: 0 | F16: =D16-E16 -> 0 | G16: =+让利!H17 -> 0 | H16: =+让利!I17 -> 0 | I16: =+G16-H16 -> 0 | J16: =I16/G16 -> #DIV/0! | K16: =+让利!K17 -> 0 | L16: =+让利!L17 -> 0 | M16: =+K16-L16 -> 0 | N16: =M16/K16 -> #DIV/0!
A17: 13 | B17: 指定分包 | C17: 元 | D17: 0 | E17: 0 | F17: =D17-E17 -> 0 | G17: =+指定分包!G13 -> 0 | H17: =+指定分包!H13 -> 0 | I17: =+G17-H17 -> 0 | J17: =I17/G17 -> #DIV/0! | K17: =+指定分包!J13 -> 0 | L17: =+指定分包!K13 -> 0 | M17: =+K17-L17 -> 0 | N17: =M17/K17 -> #DIV/0!
A18: 14 | B18: 总包服务费 | C18: 元 | D18: =895000/1.09 -> 821100.92 | E18: =-32982357.59/1.09*3.5% -> -1059066.5 | F18: =D18-E18 -> 1880167.4 | G18: =+总包服务费!H17 -> 0 | H18: =+总包服务费!I17 -> 15870.872 | I18: =+G18-H18 -> -15870.872 | J18: =I18/G18 -> #DIV/0! | K18: =+总包服务费!K17 -> 0 | L18: =+总包服务费!L17 -> -25477.751 | M18: =+K18-L18 -> 25477.751 | N18: =M18/K18 -> #DIV/0!
A19: 15 | B19: 其 它 | C19: 元 | D19: =其它!F22 -> 3385321.1 | E19: =其它!I22 -> 4496458.2 | F19: =D19-E19 -> -1111137.1 | G19: =+其它!L22 -> 0 | H19: =+其它!O22 -> 0 | I19: =+G19-H19 -> 0 | J19: =I19/G19 -> #DIV/0! | K19: =+其它!R22 -> 0 | L19: =+其它!U22 -> 0 | M19: =+K19-L19 -> 0 | N19: =M19/K19 -> #DIV/0!
A20: 16 | B20: 开源效益 | C20: 元 | D20: 0 | E20: -2289682.9 | F20: =D20-E20 -> 2289682.9 | I20: =+G20-H20 -> 0 | J20: =I20/G20 -> #DIV/0! | M20: =+K20-L20 -> 0 | N20: =M20/K20 -> #DIV/0!
B21: 合计 | C21: 元 | D21: =SUM(D5:D20) -> 1.1111371e+08 | E21: =SUM(E5:E20) -> 1.1107911e+08 | F21: =D21-E21 -> 34603.047 | G21: =SUM(G5:G20) -> 4157400.4 | H21: =SUM(H5:H20) -> 3868779.8 | I21: =G21-H21 -> 288620.55 | J21: =I21/G21 -> 0.069423325 | K21: =SUM(K5:K20) -> 47060018 | L21: =SUM(L5:L20) -> 47000639 | M21: =K21-L21 -> 59378.693 | N21: =M21/K21 -> 0.0012617652
A22: 备注：1.“预测工程竣工数据统计”数据原则上每季度调整一次。2.“预测工程竣工数据统计”中“开源效益”数据填净利润，在前期不确定增加收入时，可根据开源效益目标将该数值填入计划成本中，为负值冲减成本。3.“安全文明施工费”根据《建设工程工程量清单计价规范》GB 50500—2013规定进行数据归口。4.“开源效益”数据来源“开源效益计算表”中的“未实施部分”。
D23: （营改增后一般计税项目，价税分离，税金不列，下同）
D25: =D5+D6+D7+D8+D9 -> 88289980 | G25: =G5+G6+G7+G8+G9 -> 3433412.3 | K25: =(K5+K6+K7+K8+K9)/1.09 -> 36175930
I28: 土建数据 | J28: 本期 | K28: 累计
I29: 预算收入 | J29: =+G21-专业分包费!M581 -> 4302401.7 | K29: =+K21-专业分包费!S581 -> 46043006
I30: 实际成本 | J30: =+H21-专业分包费!P581 -> 4662323.4 | K30: =+L21-专业分包费!V581 -> 45726752
I31: 安装数据 | J31: 本期 | K31: 累计
I32: 预算收入 | J32: =+专业分包费!M581 -> -145001.38 | K32: =+专业分包费!S581 -> 1017011.9
I33: 实际成本 | J33: =+专业分包费!P581 -> -793543.58 | K33: =+专业分包费!V581 -> 1273887.6

Sheet 本期分析及总结
A1: 本期分析及总结
A2: 一、 | B2: 本期完成工程描述及累计形象部位
A3: 1 | B3: 地下室：
A4: 1.1 | B4: 地下室主体结构封顶
A5: 1.2 | B5: 地下室砌筑完成
A6: 1.3 | B6: 地下室外墙防水施工完成
A7: 1.4 | B7: 地上外墙防水：1号楼完成3-12层，2号楼完成3-12层
A8: 1.5 | B8: 地上1号楼、2号楼完成17层结构
A10: 二、 | B10: 本期项目成本情况
A11: 1 | B11: 项目成本收入数据是截止2024年4月15日
A12: 2 | B12: 实际累计产值 | C12: =+汇总表!K21/10000 -> 4706.0018 | D12: 万元
A13: 3 | B13: 实际累计成本 | C13: =+汇总表!L21/10000 -> 4700.0639 | D13: 万元
A15: 三、 | B15: 总结及纠偏措施
A16: 1 | B16: 目前项目施工阶段处于1#、2#塔楼主体施工阶段，地下室处于砌筑阶段，预测6月30日之前主体封顶；
A17: 2 | B17: 临设费用较高，由于场地限制，目前项目只能租房，后续准备主体结构封顶在首层规划临建，降低成本；

Sheet 人工费
A1: 工程项目人工费计算表
A2: 工程名称： XXX项目
A3: 序号 | B3: 分部分项名称 | C3: 项目特征 | D3: 单位 | E3: 预测工程竣工数据统计 | K3: 本期数据统计 | Q3: 累计数据统计 | W3: 备注 | Z3: 上次累计数据统计
E4: 预算收入 | H4: 计划成本 | K4: 预算收入 | N4: 实际成本 | Q4: 预算收入 | T4: 实际成本 | Z4: 预算收入
E5: 工程量 | F5: 单价 | G5: 合价 | H5: 工程量 | I5: 单价 | J5: 合计 | K5: 工程量 | L5: 单价 | M5: 合价 | N5: 工程量 | O5: 单价 | P5: 合价 | Q5: 工程量 | R5: 单价 | S5: 合价 | T5: 工程量 | U5: 单价 | V5: 合价 | Z5: 工程量
A6: 一 | B6: 地下室结构 | G6: 2347723.9 | J6: 2769234.9 | M6: =+M7+M33 -> -45348.832 | P6: =+P7+P33 -> -64500 | S6: =+S7+S33 -> 2297592.5 | V6: =+V7+V33 -> 2434226.2
A7: 1 | B7: 钢筋混凝土工程（地下） | M7: =SUM(M8:M32) -> 0 | P7: =SUM(P8:P32) -> 0 | S7: =SUM(S8:S32) -> 770848.74 | V7: =SUM(V8:V32) -> 612004.43
A8: 1.1 | B8: 垫层 C20 | C8: (1)混凝土强度等级:C20泵送商品混凝土_x000D_ (2)满足设计图纸、相关规范、招标文件及技术要求 | D8: m3 | E8: 530.03 | F8: 44.018139 | G8: 23330.934 | H8: 530.03 | I8: 180 | J8: 95405.4 | K8: =+Q8-Z8 -> 0 | L8: =+F8 -> 44.018139 | M8: =+L8*K8 -> 0 | N8: =+K8 -> 0 | O8: =+U8 -> 150 | P8: =+O8*N8 -> 0 | Q8: 530.03 | R8: =+F8 -> 44.018139 | S8: =+R8*Q8 -> 23330.934 | T8: =+Q8 -> 530.03 | U8: 150 | V8: =+U8*T8 -> 79504.5 | Z8: 530.03
A9: 1.2 | B9: 基础（筏板、柱墩、桩承台、基础梁、集水坑） C35P10 | C9: (1)混凝土强度等级:C35泵送商品混凝土，抗渗P10_x000D_ (2)补偿收缩混凝土，补偿收缩时≥0.02%_x000D_ (3)满足设计图纸、相关规范、招标文件及技术要求 | D9: m3 | E9: 3895.64 | F9: 47.755081 | G9: 186036.6 | H9: 3895.64 | I9: 48.5 | J9: 188938.54 | K9: =+Q9-Z9 -> 0 | L9: =+F9 -> 47.755081 | M9: =+L9*K9 -> 0 | N9: =+K9 -> 0 | O9: =+U9 -> 48.5 | P9: =+O9*N9 -> 0 | Q9: 3895.64 | R9: =+F9 -> 47.755081 | S9: =+R9*Q9 -> 186036.6 | T9: =+Q9 -> 3895.64 | U9: 48.5 | V9: =+U9*T9 -> 188938.54 | Z9: 3895.64
A10: 1.3 | B10: 砼墙、柱 C60 | C10: (1)混凝土强度等级:C60泵送商品混凝土_x000D_ (2)满足设计图纸、相关规范、招标文件及技术要求 | D10: m3 | E10: 1201.57 | F10: 80.439095 | G10: 96653.203 | H10: 1201.57 | I10: 48.5 | J10: 58276.145 | K10: =+Q10-Z10 -> 0 | L10: =+F10 -> 80.439095 | M10: =+L10*K10 -> 0 | N10: =+K10 -> 0 | O10: =+U10 -> 48.5 | P10: =+O10*N10 -> 0 | Q10: 1201.57 | R10: =+F10 -> 80.439095 | S10: =+R10*Q10 -> 96653.203 | T10: =+Q10 -> 1201.57 | U10: 48.5 | V10: =+U10*T10 -> 58276.145 | Z10: 1201.57
A11: 1.4 | B11: 砼墙、柱 C40 | C11: (1)混凝土强度等级:C40泵送商品混凝土_x000D_ (2)满足设计图纸、相关规范、招标文件及技术要求 | D11: m3 | E11: 182.21 | F11: 80.439095 | G11: 14656.807 | H11: 182.21 | I11: 48.5 | J11: 8837.185 | K11: =+Q11-Z11 -> 0 | L11: =+F11 -> 80.439095 | M11: =+L11*K11 -> 0 | N11: =+K11 -> 0 | O11: =+U11 -> 48.5 | P11: =+O11*N11 -> 0 | Q11: 182.21 | R11: =+F11 -> 80.439095 | S11: =+R11*Q11 -> 14656.807 | T11: =+Q11 -> 182.21 | U11: 48.5 | V11: =+U11*T11 -> 8837.185 | Z11: 182.21
A12: 1.5 | B12: 砼墙、柱 C35P10_x000D_ | C12: (1)混凝土强度等级:C35泵送商品混凝土，抗渗P10_x000D_ (2)补偿收缩混凝土，补偿收缩时≥0.02%_x000D_ (3)满足设计图纸、相关规范、招标文件及技术要求 | D12: m3 | E12: 481.52 | F12: 80.439095 | G12: 38733.033 | H12: 481.52 | I12: 48.5 | J12: 23353.72 | K12: =+Q12-Z12 -> 0 | L12: =+F12 -> 80.439095 | M12: =+L12*K12 -> 0 | N12: =+K12 -> 0 | O12: =+U12 -> 48.5 | P12: =+O12*N12 -> 0 | Q12: 481.52 | R12: =+F12 -> 80.439095 | S12: =+R12*Q12 -> 38733.033 | T12: =+Q12 -> 481.52 | U12: 48.5 | V12: =+U12*T12 -> 23353.72 | Z12: 481.52
A13: 1.6 | B13: 砼墙、柱 C35P8_x000D_ | C13: (1)混凝土强度等级:C35泵送商品混凝土，抗渗P8_x000D_ (2)补偿收缩混凝土，补偿收缩时≥0.02%_x000D_ (3)满足设计图纸、相关规范、招标文件及技术要求 | D13: m3 | E13: 394.28 | F13: 80.439095 | G13: 31715.526 | H13: 394.28 | I13: 48.5 | J13: 19122.58 | K13: =+Q13-Z13 -> 0 | L13: =+F13 -> 80.439095 | M13: =+L13*K13 -> 0 | N13: =+K13 -> 0 | O13: =+U13 -> 48.5 | P13: =+O13*N13 -> 0 | Q13: 394.28 | R13: =+F13 -> 80.439095 | S13: =+R13*Q13 -> 31715.526 | T13: =+Q13 -> 394.28 | U13: 48.5 | V13: =+U13*T13 -> 19122.58 | Z13: 394.28
A14: 1.7 | B14: 砼墙、柱 C35P6_x000D_ | C14: (1)混凝土强度等级:C35泵送商品混凝土，抗渗P6_x000D_ (2)补偿收缩混凝土，补偿收缩时≥0.02%_x000D_ (3)满足设计图纸、相关规范、招标文件及技术要求 | D14: m3 | E14: 560.18 | F14: 80.439095 | G14: 45060.372 | H14: 560.18 | I14: 48.5 | J14: 27168.73 | K14: =+Q14-Z14 -> 0 | L14: =+F14 -> 80.439095 | M14: =+L14*K14 -> 0 | N14: =+K14 -> 0 | O14: =+U14 -> 48.5 | P14: =+O14*N14 -> 0 | Q14: 560.18 | R14: =+F14 -> 80.439095 | S14: =+R14*Q14 -> 45060.372 | T14: =+Q14 -> 560.18 | U14: 48.5 | V14: =+U14*T14 -> 27168.73 | Z14: 560.18
A15: 1.8 | B15: 砼墙、柱 C35_x000D_ | C15: (1)混凝土强度等级:C35泵送商品混凝土_x000D_ (2)满足设计图纸、相关规范、招标文件及技术要求 | D15: m3 | E15: 335.64 | F15: 80.439095 | G15: 26998.578 | H15: 335.64 | I15: 48.5 | J15: 16278.54 | K15: =+Q15-Z15 -> 0 | L15: =+F15 -> 80.439095 | M15: =+L15*K15 -> 0 | N15: =+K15 -> 0 | O15: =+U15 -> 48.5 | P15: =+O15*N15 -> 0 | Q15: 335.64 | R15: =+F15 -> 80.439095 | S15: =+R15*Q15 -> 26998.578 | T15: =+Q15 -> 335.64 | U15: 48.5 | V15: =+U15*T15 -> 16278.54 | Z15: 335.64
A16: 1.9 | B16: 矩形柱 C35 | C16: (1)混凝土强度等级:C35泵送商品混凝土_x000D_ (2)满足设计图纸、相关规范、招标文件及技术要求 | D16: m3 | E16: 39.15 | F16: 80.439095 | G16: 3149.1906 | H16: 39.15 | I16: 48.5 | J16: 1898.775 | K16: =+Q16-Z16 -> 0 | L16: =+F16 -> 80.439095 | M16: =+L16*K16 -> 0 | N16: =+K16 -> 0 | O16: =+U16 -> 48.5 | P16: =+O16*N16 -> 0 | Q16: 39.15 | R16: =+F16 -> 80.439095 | S16: =+R16*Q16 -> 3149.1906 | T16: =+Q16 -> 39.15 | U16: 48.5 | V16: =+U16*T16 -> 1898.775 | Z16: 39.15
A17: 1.1 | B17: 有梁板 (梁、板) C35P6 | C17: (1)混凝土强度等级:C35泵送商品混凝土,P6_x000D_ (2)补偿收缩混凝土，补偿收缩时≥0.02%_x000D_ (3)满足设计图纸、相关规范、招标文件及技术要求 | D17: m3 | E17: 1349.99 | F17: 73.230781 | G17: 98860.822 | H17: 1349.99 | I17: 48.5 | J17: 65474.515 | K17: =+Q17-Z17 -> 0 | L17: =+F17 -> 73.230781 | M17: =+L17*K17 -> 0 | N17: =+K17 -> 0 | O17: =+U17 -> 48.5 | P17: =+O17*N17 -> 0 | Q17: 1349.99 | R17: =+F17 -> 73.230781 | S17: =+R17*Q17 -> 98860.822 | T17: =+Q17 -> 1349.99 | U17: 48.5 | V17: =+U17*T17 -> 65474.515 | Z17: 1349.99
A18: 1.11 | B18: 有梁板 (梁、板) C35 | C18: (1)混凝土强度等级:C35泵送商品混凝土_x000D_ (2)满足设计图纸、相关规范、招标文件及技术要求 | D18: m3 | E18: 1871.42 | F18: 73.230781 | G18: 137045.55 | H18: 1871.42 | I18: 48.5 | J18: 90763.87 | K18: =+Q18-Z18 -> 0 | L18: =+F18 -> 73.230781 | M18: =+L18*K18 -> 0 | N18: =+K18 -> 0 | O18: =+U18 -> 48.5 | P18: =+O18*N18 -> 0 | Q18: 1871.42 | R18: =+F18 -> 73.230781 | S18: =+R18*Q18 -> 137045.55 | T18: =+Q18 -> 1871.42 | U18: 48.5 | V18: =+U18*T18 -> 90763.87 | Z18: 1871.42
A19: 1.12 | B19: 有梁板 (梁、板)坡道 C35 | C19: (1)混凝土强度等级:C35泵送商品混凝土_x000D_ (2)满足设计图纸、相关规范、招标文件及技术要求 | D19: m3 | E19: 155.94 | F19: 73.230781 | G19: 11419.608 | H19: 155.94 | I19: 48.5 | J19: 7563.09 | K19: =+Q19-Z19 -> 0 | L19: =+F19 -> 73.230781 | M19: =+L19*K19 -> 0 | N19: =+K19 -> 0 | O19: =+U19 -> 48.5 | P19: =+O19*N19 -> 0 | Q19: 155.94 | R19: =+F19 -> 73.230781 | S19: =+R19*Q19 -> 11419.608 | T19: =+Q19 -> 155.94 | U19: 48.5 | V19: =+U19*T19 -> 7563.09 | Z19: 155.94
... A31: 1.24 | B31: C20素混凝土（坡道位置）_x000D_ | C31: (1)C20素混凝土_x000D_ (2)满足设计图纸、相关规范、招标文件及技术要求 | D31: m3 | E31: 44.04 | F31: 52.772447 | G31: 2324.0986 | H31: 44.04 | I31: 50 | J31: 2202 | K31: =+Q31-Z31 -> 0 | L31: =+F31 -> 52.772447 | M31: =+L31*K31 -> 0 | N31: =+K31 -> 0 | O31: =+U31 -> 48.5 | P31: =+O31*N31 -> 0 | Q31: 0 | R31: =+F31 -> 52.772447 | S31: =+R31*Q31 -> 0 | T31: =+Q31 -> 0 | U31: 48.5 | V31: =+U31*T31 -> 0 | Z31: 0
A32: 1.25 | B32: 混凝土泵送费扣减 | D32: 项 | E32: 1 | F32: -68531.026 | G32: -68531.026 | H32: 1 | J32: 0 | K32: =+Q32-Z32 -> 0 | N32: =+K32 -> 0 | S32: =+R32*Q32 -> 0 | V32: =+U32*T32 -> 0
A33: 2 | B33: 钢筋工程 | G33: =SUM(G34:G61) -> 1608805 | J33: =SUM(J34:J61) -> 1901636.7 | M33: =SUM(M34:M61) -> -45348.832 | P33: =SUM(P34:P61) -> -64500 | S33: =SUM(S34:S61) -> 1526743.7 | V33: =SUM(V34:V61) -> 1822221.7
A34: 2.1 | B34: 现浇构件钢筋 | C34: (1)钢筋种类、规格:拉结筋制安(HPB300)φ6mm_x000D_ (2)满足设计图纸、相关规范、招标文件及技术要求 | D34: t | E34: 4.5 | F34: 1673.7231 | G34: 7531.754 | H34: 4.5 | I34: 1290 | J34: 5805 | K34: =+Q34-Z34 -> 0 | L34: 1673.7231 | M34: =+L34*K34 -> 0 | N34: =+K34 -> 0 | O34: 1290 | P34: =+O34*N34 -> 0 | R34: 1673.7231 | S34: =+R34*Q34 -> 0 | T34: =+Q34 -> 0 | U34: 1290 | V34: =+U34*T34 -> 0
A35: 2.2 | B35: 现浇构件钢筋 | C35: (1)钢筋种类、规格:圆钢制安 φ6mm_x000D_ (2)满足设计图纸、相关规范、招标文件及技术要求 | D35: t | E35: 0.2 | F35: 1235.7232 | G35: 247.14464 | H35: 0.2 | I35: 1290 | J35: 258 | K35: =+Q35-Z35 -> 0 | L35: 1235.7232 | M35: =+L35*K35 -> 0 | N35: =+K35 -> 0 | O35: 1290 | P35: =+O35*N35 -> 0 | R35: 1235.7232 | S35: =+R35*Q35 -> 0 | T35: =+Q35 -> 0 | U35: 1290 | V35: =+U35*T35 -> 0
A36: 2.3 | B36: 现浇构件钢筋 | C36: (1)钢筋种类、规格:圆钢制安 φ8~10mm以上_x000D_ (2)满足设计图纸、相关规范、招标文件及技术要求 | D36: t | E36: 0.2 | F36: 953.90656 | G36: 190.78131 | H36: 0.2 | I36: 1290 | J36: 258 | K36: =+Q36-Z36 -> 0 | L36: 953.90656 | M36: =+L36*K36 -> 0 | N36: =+K36 -> 0 | O36: 1290 | P36: =+O36*N36 -> 0 | R36: 953.90656 | S36: =+R36*Q36 -> 0 | T36: =+Q36 -> 0 | U36: 1290 | V36: =+U36*T36 -> 0
A37: 2.4 | B37: 现浇构件钢筋 | C37: (1)钢筋种类、规格:螺纹钢制安Ⅲ级(HRB400E)φ6mm_x000D_ (2)满足设计图纸、相关规范、招标文件及技术要求 | D37: t | E37: 0.022 | F37: 1024.4911 | G37: 22.538805 | H37: 0.022 | I37: 1290 | J37: 28.38 | K37: =+Q37-Z37 -> 0 | L37: 1024.4911 | M37: =+L37*K37 -> 0 | N37: =+K37 -> 0 | O37: 1290 | P37: =+O37*N37 -> 0 | R37: 1024.4911 | S37: =+R37*Q37 -> 0 | T37: =+Q37 -> 0 | U37: 1290 | V37: =+U37*T37 -> 0
A38: 2.5 | B38: 现浇构件钢筋 | C38: (1)钢筋种类、规格:螺纹钢制安Ⅲ级(HRB400E)φ8mm_x000D_ (2)满足设计图纸、相关规范、招标文件及技术要求 | D38: t | E38: 36.245 | F38: 1024.4911 | G38: 37132.681 | H38: 36.245 | I38: 1290 | J38: 46756.05 | K38: =+Q38-Z38 -> 0 | L38: 1024.4911 | M38: =+L38*K38 -> 0 | N38: =+K38 -> 0 | O38: 1290 | P38: =+O38*N38 -> 0 | Q38: 36.245 | R38: 1024.4911 | S38: =+R38*Q38 -> 37132.681 | T38: =+Q38 -> 36.245 | U38: 1290 | V38: =+U38*T38 -> 46756.05 | Z38: 36.245
A39: 2.6 | B39: 现浇构件钢筋 | C39: (1)钢筋种类、规格:螺纹钢制安Ⅲ级(HRB400E)φ10mm_x000D_ (2)满足设计图纸、相关规范、招标文件及技术要求 | D39: t | E39: 177.258 | F39: 1024.4911 | G39: 181599.25 | H39: 177.258 | I39: 1290 | J39: 228662.82 | K39: =+Q39-Z39 -> 0 | L39: 1024.4911 | M39: =+L39*K39 -> 0 | N39: =+K39 -> 0 | O39: 1290 | P39: =+O39*N39 -> 0 | Q39: 177.258 | R39: 1024.4911 | S39: =+R39*Q39 -> 181599.25 | T39: =+Q39 -> 177.258 | U39: 1290 | V39: =+U39*T39 -> 228662.82 | Z39: 177.258
A40: 2.7 | B40: 现浇构件钢筋 | C40: (1)钢筋种类、规格:螺纹钢制安Ⅲ级(HRB400E)φ12mm_x000D_ (2)满足设计图纸、相关规范、招标文件及技术要求 | D40: t | E40: 313.589 | F40: 906.97664 | G40: 284417.9 | H40: 313.589 | I40: 1290 | J40: 404529.81 | K40: =+Q40-Z40 -> -50 | L40: 906.97664 | M40: =+L40*K40 -> -45348.832 | N40: =+K40 -> -50 | O40: 1290 | P40: =+O40*N40 -> -64500 | Q40: =313.589-50 -> 263.589 | R40: 906.97664 | S40: =+R40*Q40 -> 239069.07 | T40: =+Q40 -> 263.589 | U40: 1290 | V40: =+U40*T40 -> 340029.81 | Z40: 313.589
A41: 2.8 | B41: 现浇构件钢筋 | C41: (1)钢筋种类、规格:螺纹钢制安Ⅲ级(HRB400E)φ14mm_x000D_ (2)满足设计图纸、相关规范、招标文件及技术要求 | D41: t | E41: 72.128 | F41: 906.97664 | G41: 65418.411 | H41: 72.128 | I41: 1290 | J41: 93045.12 | K41: =+Q41-Z41 -> 0 | L41: 906.97664 | M41: =+L41*K41 -> 0 | N41: =+K41 -> 0 | O41: 1290 | P41: =+O41*N41 -> 0 | Q41: 72.128 | R41: 906.97664 | S41: =+R41*Q41 -> 65418.411 | T41: =+Q41 -> 72.128 | U41: 1290 | V41: =+U41*T41 -> 93045.12 | Z41: 72.128
A42: 2.9 | B42: 现浇构件钢筋 | C42: (1)钢筋种类、规格:螺纹钢制安Ⅲ级(HRB400E)φ16mm_x000D_ (2)满足设计图纸、相关规范、招标文件及技术要求 | D42: t | E42: 320.691 | F42: 906.97664 | G42: 290859.25 | H42: 320.691 | I42: 1290 | J42: 413691.39 | K42: =+Q42-Z42 -> 0 | L42: 906.97664 | M42: =+L42*K42 -> 0 | N42: =+K42 -> 0 | O42: 1290 | P42: =+O42*N42 -> 0 | Q42: 320.691 | R42: 906.97664 | S42: =+R42*Q42 -> 290859.25 | T42: =+Q42 -> 320.691 | U42: 1290 | V42: =+U42*T42 -> 413691.39 | Z42: 320.691
A43: 2.1 | B43: 现浇构件钢筋 | C43: (1)钢筋种类、规格:螺纹钢制安Ⅲ级(HRB400E)φ18mm_x000D_ (2)满足设计图纸、相关规范、招标文件及技术要求 | D43: t | E43: 65.535 | F43: 906.97664 | G43: 59438.714 | H43: 65.535 | I43: 1290 | J43: 84540.15 | K43: =+Q43-Z43 -> 0 | L43: 906.97664 | M43: =+L43*K43 -> 0 | N43: =+K43 -> 0 | O43: 1290 | P43: =+O43*N43 -> 0 | Q43: 65.535 | R43: 906.97664 | S43: =+R43*Q43 -> 59438.714 | T43: =+Q43 -> 65.535 | U43: 1290 | V43: =+U43*T43 -> 84540.15 | Z43: 65.535
A44: 2.11 | B44: 现浇构件钢筋 | C44: (1)钢筋种类、规格:螺纹钢制安Ⅲ级(HRB400E)φ20mm_x000D_ (2)满足设计图纸、相关规范、招标文件及技术要求 | D44: t | E44: 84.293 | F44: 906.97664 | G44: 76451.782 | H44: 84.293 | I44: 1290 | J44: 108737.97 | K44: =+Q44-Z44 -> 0 | L44: 906.97664 | M44: =+L44*K44 -> 0 | N44: =+K44 -> 0 | O44: 1290 | P44: =+O44*N44 -> 0 | Q44: 84.293 | R44: 906.97664 | S44: =+R44*Q44 -> 76451.782 | T44: =+Q44 -> 84.293 | U44: 1290 | V44: =+U44*T44 -> 108737.97 | Z44: 84.293
A45: 2.12 | B45: 现浇构件钢筋 | C45: (1)钢筋种类、规格:螺纹钢制安Ⅲ级(HRB400E)φ22mm_x000D_ (2)满足设计图纸、相关规范、招标文件及技术要求 | D45: t | E45: 59.776 | F45: 906.97664 | G45: 54215.436 | H45: 59.776 | I45: 1290 | J45: 77111.04 | K45: =+Q45-Z45 -> 0 | L45: 906.97664 | M45: =+L45*K45 -> 0 | N45: =+K45 -> 0 | O45: 1290 | P45: =+O45*N45 -> 0 | Q45: 59.776 | R45: 906.97664 | S45: =+R45*Q45 -> 54215.436 | T45: =+Q45 -> 59.776 | U45: 1290 | V45: =+U45*T45 -> 77111.04 | Z45: 59.776
A46: 2.13 | B46: 现浇构件钢筋 | C46: (1)钢筋种类、规格:螺纹钢制安Ⅲ级(HRB400E)φ25mm_x000D_ (2)满足设计图纸、相关规范、招标文件及技术要求 | D46: t | E46: 77.28 | F46: 906.97664 | G46: 70091.155 | H46: 77.28 | I46: 1290 | J46: 99691.2 | K46: =+Q46-Z46 -> 0 | L46: 906.97664 | M46: =+L46*K46 -> 0 | N46: =+K46 -> 0 | O46: 1290 | P46: =+O46*N46 -> 0 | Q46: 77.28 | R46: 906.97664 | S46: =+R46*Q46 -> 70091.155 | T46: =+Q46 -> 77.28 | U46: 1290 | V46: =+U46*T46 -> 99691.2 | Z46: 77.28
A47: 2.14 | B47: 现浇构件钢筋 | C47: (1)钢筋种类、规格:螺纹钢制安Ⅲ级(HRB400E)φ28~32mm_x000D_ (2)满足设计图纸、相关规范、招标文件及技术要求 | D47: t | E47: 10.911 | F47: 805.99385 | G47: 8794.1989 | H47: 10.911 | I47: 1290 | J47: 14075.19 | K47: =+Q47-Z47 -> 0 | L47: 805.99385 | M47: =+L47*K47 -> 0 | N47: =+K47 -> 0 | O47: 1290 | P47: =+O47*N47 -> 0 | Q47: 10.911 | R47: 805.99385 | S47: =+R47*Q47 -> 8794.1989 | T47: =+Q47 -> 10.911 | U47: 1290 | V47: =+U47*T47 -> 14075.19 | Z47: 10.911
A48: 2.15 | B48: 现浇构件钢筋 | C48: (1)钢筋种类、规格:螺纹钢制安Ⅲ级(HRB400E)φ36~40mm_x000D_ (2)满足设计图纸、相关规范、招标文件及技术要求 | D48: t | E48: 0.2 | F48: 805.99385 | G48: 161.19877 | H48: 0.2 | I48: 1290 | J48: 258 | K48: =+Q48-Z48 -> 0 | L48: 805.99385 | M48: =+L48*K48 -> 0 | N48: =+K48 -> 0 | O48: 1290 | P48: =+O48*N48 -> 0 | Q48: 0 | R48: 805.99385 | S48: =+R48*Q48 -> 0 | T48: =+Q48 -> 0 | U48: 1290 | V48: =+U48*T48 -> 0 | Z48: 0
A49: 2.16 | B49: 现浇构件钢筋 （箍筋） | C49: (1)钢筋种类、规格:圆钢制安 φ6mm_x000D_ (2)满足设计图纸、相关规范、招标文件及技术要求 | D49: t | E49: 2.469 | F49: 1706.5494 | G49: 4213.4705 | H49: 2.469 | I49: 1290 | J49: 3185.01 | K49: =+Q49-Z49 -> 0 | L49: 1706.5494 | M49: =+L49*K49 -> 0 | N49: =+K49 -> 0 | O49: 1290 | P49: =+O49*N49 -> 0 | R49: 1706.5494 | S49: =+R49*Q49 -> 0 | T49: =+Q49 -> 0 | U49: 1290 | V49: =+U49*T49 -> 0
A50: 2.17 | B50: 现浇构件钢筋 （箍筋） | C50: (1)钢筋种类、规格:圆钢制安 φ8~10mm_x000D_ (2)满足设计图纸、相关规范、招标文件及技术要求 | D50: t | E50: 1.676 | F50: 1038.8603 | G50: 1741.1299 | H50: 1.676 | I50: 1290 | J50: 2162.04 | K50: =+Q50-Z50 -> 0 | L50: 1038.8603 | M50: =+L50*K50 -> 0 | N50: =+K50 -> 0 | O50: 1290 | P50: =+O50*N50 -> 0 | R50: 1038.8603 | S50: =+R50*Q50 -> 0 | T50: =+Q50 -> 0 | U50: 1290 | V50: =+U50*T50 -> 0
A51: 2.18 | B51: 现浇构件钢筋 （箍筋） | C51: (1)钢筋种类、规格:螺纹钢制安Ⅲ级(HRB400E)φ6mm_x000D_ (2)满足设计图纸、相关规范、招标文件及技术要求 | D51: t | E51: 5.325 | F51: 1706.5494 | G51: 9087.3756 | H51: 5.325 | I51: 1290 | J51: 6869.25 | K51: =+Q51-Z51 -> 0 | L51: 1706.5494 | M51: =+L51*K51 -> 0 | N51: =+K51 -> 0 | O51: 1290 | P51: =+O51*N51 -> 0 | Q51: 5.325 | R51: 1706.5494 | S51: =+R51*Q51 -> 9087.3756 | T51: =+Q51 -> 5.325 | U51: 1290 | V51: =+U51*T51 -> 6869.25 | Z51: 5.325
...

Sheet 材料费
A1: 工程项目材料费计算表
A2: =[1]人工费!A2 -> 工程名称：
A3: 序号 | B3: 材料名称 | C3: 材料规格 | D3: 单位 | E3: 预测工程竣工数据统计 | K3: 本期数据统计 | Q3: 累计数据统计 | W3: 备注 | Z3: 上次累计数据统计
E4: 预算收入 | H4: 计划成本 | K4: 预算收入 | N4: 实际成本 | Q4: 预算收入 | T4: 实际成本 | Z4: 实际成本
E5: 工程量 | F5: 单价 | G5: 合价 | H5: 工程量 | I5: 单价 | J5: 合价 | K5: 工程量 | L5: 单价 | M5: 合价 | N5: 工程量 | O5: 单价 | P5: 合价 | Q5: 工程量 | R5: 单价 | S5: 合价 | T5: 工程量 | U5: 单价 | V5: 合价 | Z5: 工程量 | AA5: 单价 | AB5: 合价
A6: 一 | B6: 地下室结构 | E6: 0 | G6: =+G7+G33 -> 12707131 | H6: 0 | J6: =+J7+J33 -> 9739695.9 | M6: =+M7+M33 -> -203714.54 | P6: =+P7+P33 -> 2668225.5 | S6: =+S7+S33 -> 12342703 | V6: =+V7+V33 -> 15952817 | AB6: 13266956
A7: 1 | B7: 钢筋混凝土工程（地下） | E7: 0 | F7: 0 | G7: =SUM(G8:G32) -> 6709892.8 | H7: 0 | J7: =SUM(J8:J32) -> 4576549.5 | K7: =SUM(K8:K31) -> 0 | M7: =SUM(M8:M32) -> 0 | N7: =SUM(N12:N30) -> 11962 | P7: =SUM(P8:P32) -> 1186598.9 | Q7: =SUM(Q8:Q31) -> 11509.41 | S7: =SUM(S8:S32) -> 6595980.8 | T7: =SUM(T8:T31) -> 16225.5 | V7: =SUM(V8:V32) -> 6609727.1 | Z7: 15269.5 | AB7: 6227130.8
A8: 1.1 | B8: 垫层 C20 | C8: (1)混凝土强度等级:C20泵送商品混凝土_x000D_ (2)满足设计图纸、相关规范、招标文件及技术要求 | D8: m3 | E8: 530.03 | F8: 492.40373 | G8: =+F8*E8 -> 260988.75 | H8: 530.03 | I8: 332.50971 | J8: =+I8*H8 -> 176240.12 | K8: =+人工费!K8 -> 0 | L8: =+R8 -> 492.40373 | M8: =+L8*K8 -> 0 | N8: =+T8-Z8 -> -230.5 | O8: =+U8 -> 330.76633 | P8: =+N8*O8 -> -76241.639 | Q8: =+人工费!Q8 -> 530.03 | R8: 492.40373 | S8: =+R8*Q8 -> 260988.75 | T8: 257.5 | U8: 330.76633 | V8: =+U8*T8 -> 85172.33 | W8: 细砼C20 | Z8: 488 | AA8: 333.46078 | AB8: 162728.86
A9: 1.2 | B9: 基础（筏板、柱墩、桩承台、基础梁、集水坑） C35P10 | C9: (1)混凝土强度等级:C35泵送商品混凝土，抗渗P10 (2)补偿收缩混凝土，补偿收缩时≥0.02% (3)满足设计图纸、相关规范、招标文件及技术要求 | D9: m3 | E9: 3895.64 | F9: 575.56491 | G9: =+F9*E9 -> 2242193.7 | H9: 3895.64 | I9: 388.63689 | J9: =+I9*H9 -> 1513989.4 | K9: =+人工费!K9 -> 0 | L9: =+R9 -> 575.56491 | M9: =+L9*K9 -> 0 | N9: =+T9-Z9 -> -7067 | O9: =+U9 -> 330.17464 | P9: =+N9*O9 -> -2333344.2 | Q9: =+人工费!Q9 -> 3895.64 | R9: 575.56491 | S9: =+R9*Q9 -> 2242193.7 | T9: 491 | U9: 330.17464 | V9: =+U9*T9 -> 162115.75 | W9: 商砼C20 | Z9: 7558 | AA9: 397.97682 | AB9: 3007908.8
A10: 1.3 | B10: 砼墙、柱 C60 | C10: (1)混凝土强度等级:C60泵送商品混凝土 (2)满足设计图纸、相关规范、招标文件及技术要求 | D10: m3 | E10: 1201.57 | F10: 647.44888 | G10: =+F10*E10 -> 777955.15 | H10: 1201.57 | I10: 447.05485 | J10: =+I10*H10 -> 537167.7 | K10: =+人工费!K10 -> 0 | L10: =+R10 -> 647.44888 | M10: =+L10*K10 -> 0 | N10: =+T10-Z10 -> -2978.5 | O10: =+U10 -> 358.37068 | P10: =+N10*O10 -> -1067407.1 | Q10: =+人工费!Q10 -> 1201.57 | R10: 647.44888 | S10: =+R10*Q10 -> 777955.15 | T10: 36.5 | U10: 358.37068 | V10: =+U10*T10 -> 13080.53 | W10: 细砼C25 | Z10: 3015 | AA10: 449.36519 | AB10: 1354836
A11: 1.4 | B11: 砼墙、柱 C40 | C11: (1)混凝土强度等级:C40泵送商品混凝土 (2)满足设计图纸、相关规范、招标文件及技术要求 | D11: m3 | E11: 182.21 | F11: 564.5343 | G11: =+F11*E11 -> 102863.79 | H11: 182.21 | I11: 388.70631 | J11: =+I11*H11 -> 70826.177 | K11: =+人工费!K11 -> 0 | L11: =+R11 -> 564.5343 | M11: =+L11*K11 -> 0 | N11: =+T11-Z11 -> -762 | O11: =+U11 -> 359.565 | P11: =+N11*O11 -> -273988.53 | Q11: =+人工费!Q11 -> 182.21 | R11: 564.5343 | S11: =+R11*Q11 -> 102863.79 | T11: 6 | U11: 359.565 | V11: =+U11*T11 -> 2157.39 | W11: 商砼C25 | Z11: 768 | AA11: 401.71936 | AB11: 308520.47
A12: 1.5 | B12: 砼墙、柱 C35P10_x000D_ | C12: (1)混凝土强度等级:C35泵送商品混凝土，抗渗P10_x000D_ (2)补偿收缩混凝土，补偿收缩时≥0.02%_x000D_ (3)满足设计图纸、相关规范、招标文件及技术要求 | D12: m3 | E12: 481.52 | F12: 575.56491 | G12: =+F12*E12 -> 277146.02 | H12: 481.52 | I12: 388.63689 | J12: =+I12*H12 -> 187136.44 | K12: =+人工费!K12 -> 0 | L12: =+R12 -> 575.56491 | M12: =+L12*K12 -> 0 | N12: =+T12-Z12 -> -222 | O12: =+U12 -> 367.05226 | P12: =+N12*O12 -> -81485.601 | Q12: =+人工费!Q12 -> 481.52 | R12: 575.56491 | S12: =+R12*Q12 -> 277146.02 | T12: 1142.5 | U12: 367.05226 | V12: =+U12*T12 -> 419357.2 | W12: 商砼C30 | Z12: 1364.5 | AA12: 373.9623 | AB12: 510271.56
A13: 1.6 | B13: 砼墙、柱 C35P8_x000D_ | C13: (1)混凝土强度等级:C35泵送商品混凝土，抗渗P8_x000D_ (2)补偿收缩混凝土，补偿收缩时≥0.02%_x000D_ (3)满足设计图纸、相关规范、招标文件及技术要求 | D13: m3 | E13: 394.28 | F13: 573.95253 | G13: =+F13*E13 -> 226298 | H13: 394.28 | I13: 387.37476 | J13: =+I13*H13 -> 152734.12 | K13: =+人工费!K13 -> 0 | L13: =+R13 -> 573.95253 | M13: =+L13*K13 -> 0 | N13: =+T13-Z13 -> -1193 | O13: =+U13 -> 381.905 | P13: =+V13-AB13 -> -527724.68 | Q13: =+人工费!Q13 -> 394.28 | R13: 573.95253 | S13: =+R13*Q13 -> 226298 | T13: 3 | U13: 381.905 | V13: =+U13*T13 -> 1145.715 | W13: C30 +10%膨胀剂 | Z13: 1196 | AA13: 442.19932 | AB13: 528870.39
A14: 1.7 | B14: 砼墙、柱 C35P6_x000D_ | C14: (1)混凝土强度等级:C35泵送商品混凝土，抗渗P6_x000D_ (2)补偿收缩混凝土，补偿收缩时≥0.02%_x000D_ (3)满足设计图纸、相关规范、招标文件及技术要求 | D14: m3 | E14: 560.18 | F14: 572.33066 | G14: =+F14*E14 -> 320608.19 | H14: 560.18 | I14: 386.11262 | J14: =+I14*H14 -> 216292.57 | K14: =+人工费!K14 -> 0 | L14: =+R14 -> 572.33066 | M14: =+L14*K14 -> 0 | N14: =+T14-Z14 -> -595 | O14: =+U14 -> 0 | P14: =+V14-AB14 -> -256762.7 | Q14: =+人工费!Q14 -> 560.18 | R14: 572.33066 | S14: =+R14*Q14 -> 320608.19 | T14: 0 | U14: 0 | V14: =+U14*T14 -> 0 | W14: C30 P6 | Z14: 595 | AA14: 431.53395 | AB14: 256762.7
A15: 1.8 | B15: 砼墙、柱 C35_x000D_ | C15: (1)混凝土强度等级:C35泵送商品混凝土_x000D_ (2)满足设计图纸、相关规范、招标文件及技术要求 | D15: m3 | E15: 335.64 | F15: 545.58402 | G15: =+F15*E15 -> 183119.82 | H15: 335.64 | I15: 381.06408 | J15: =+I15*H15 -> 127900.35 | K15: =+人工费!K15 -> 0 | L15: =+R15 -> 545.58402 | M15: =+L15*K15 -> 0 | N15: =+T15-Z15 -> 413 | O15: =+U15 -> 393.29257 | P15: =+V15-AB15 -> 162429.83 | Q15: =+人工费!Q15 -> 335.64 | R15: 545.58402 | S15: =+R15*Q15 -> 183119.82 | T15: 413 | U15: 393.29257 | V15: =+U15*T15 -> 162429.83 | W15: C30 P8+8%膨胀剂 | AB15: 0
A16: 1.9 | B16: 矩形柱 C35 | C16: (1)混凝土强度等级:C35泵送商品混凝土_x000D_ (2)满足设计图纸、相关规范、招标文件及技术要求 | D16: m3 | E16: 39.15 | F16: 545.58402 | G16: =+F16*E16 -> 21359.614 | H16: 39.15 | I16: 381.06408 | J16: =+I16*H16 -> 14918.659 | K16: =+人工费!K16 -> 0 | L16: =+R16 -> 545.58402 | M16: =+L16*K16 -> 0 | N16: =+T16-Z16 -> 1956.5 | O16: =+U16 -> 375.54733 | P16: =+V16-AB16 -> 734758.36 | Q16: =+人工费!Q16 -> 39.15 | R16: 545.58402 | S16: =+R16*Q16 -> 21359.614 | T16: 1956.5 | U16: 375.54733 | V16: =+U16*T16 -> 734758.36 | W16: 商砼C35 | AB16: 0
A17: 1.1 | B17: 有梁板 (梁、板) C35P6 | C17: (1)混凝土强度等级:C35泵送商品混凝土,P6_x000D_ (2)补偿收缩混凝土，补偿收缩时≥0.02%_x000D_ (3)满足设计图纸、相关规范、招标文件及技术要求 | D17: m3 | E17: 1349.99 | F17: 572.33066 | G17: =+F17*E17 -> 772640.66 | H17: 1349.99 | I17: 386.11262 | J17: =+I17*H17 -> 521248.18 | K17: =+人工费!K17 -> 0 | L17: =+R17 -> 572.33066 | M17: =+L17*K17 -> 0 | N17: =+T17-Z17 -> 0 | O17: =+U17 -> 0 | P17: =+V17-AB17 -> 0 | Q17: =+人工费!Q17 -> 1349.99 | R17: 572.33066 | S17: =+R17*Q17 -> 772640.66 | T17: 0 | U17: 0 | V17: =+U17*T17 -> 0 | W17: C35 P6补偿收缩时≥0.02% | AB17: 0
A18: 1.11 | B18: 有梁板 (梁、板) C35 | C18: (1)混凝土强度等级:C35泵送商品混凝土_x000D_ (2)满足设计图纸、相关规范、招标文件及技术要求 | D18: m3 | E18: 1871.42 | F18: 545.58402 | G18: =+F18*E18 -> 1021016.8 | H18: 1871.42 | I18: 381.06408 | J18: =+I18*H18 -> 713130.94 | K18: =+人工费!K18 -> 0 | L18: =+R18 -> 545.58402 | M18: =+L18*K18 -> 0 | N18: =+T18-Z18 -> 771 | O18: =+U18 -> 408.21484 | P18: =+V18-AB18 -> 314733.64 | Q18: =+人工费!Q18 -> 1871.42 | R18: 545.58402 | S18: =+R18*Q18 -> 1021016.8 | T18: 771 | U18: 408.21484 | V18: =+U18*T18 -> 314733.64 | W18: C35 P8+8%膨胀剂 | AB18: 0
A19: 1.12 | B19: 有梁板 (梁、板)坡道 C35 | C19: (1)混凝土强度等级:C35泵送商品混凝土_x000D_ (2)满足设计图纸、相关规范、招标文件及技术要求 | D19: m3 | E19: 155.94 | F19: 545.58402 | G19: =+F19*E19 -> 85078.372 | H19: 155.94 | I19: 381.06408 | J19: =+I19*H19 -> 59423.132 | K19: =+人工费!K19 -> 0 | L19: =+R19 -> 545.58402 | M19: =+L19*K19 -> 0 | N19: =+T19-Z19 -> 315 | O19: =+U19 -> 380.72816 | P19: =+V19-AB19 -> 119929.37 | Q19: =+人工费!Q19 -> 155.94 | R19: 545.58402 | S19: =+R19*Q19 -> 85078.372 | T19: 315 | U19: 380.72816 | V19: =+U19*T19 -> 119929.37 | W19: C35 P10 | AB19: 0
A20: 1.13 | B20: 后浇带 基础 C40P10 | C20: (1)混凝土强度等级:C40泵送商品混凝土,P10_x000D_ (2)补偿收缩混凝土，补偿收缩时≥0.03%_x000D_ (3)满足设计图纸、相关规范、招标文件及技术要求 | D20: m3 | E20: 141.94 | F20: 593.72797 | G20: =+F20*E20 -> 84273.748 | H20: 141.94 | I20: 396.27913 | J20: =+I20*H20 -> 56247.859 | K20: =+人工费!K20 -> 0 | L20: =+R20 -> 593.72797 | M20: =+L20*K20 -> 0 | N20: =+T20-Z20 -> 4515.5 | O20: =+U20 -> 407.15036 | P20: =+V20-AB20 -> 1838487.5 | Q20: =+人工费!Q20 -> 141.94 | R20: 593.72797 | S20: =+R20*Q20 -> 84273.748 | T20: 4515.5 | U20: 407.15036 | V20: =+U20*T20 -> 1838487.5 | W20: C35 P10+8%膨胀剂 | AB20: 0
A21: 1.14 | B21: 后浇带 梁、楼板、墙 C40P8 | C21: (1)混凝土强度等级:C40泵送商品混凝土,P8_x000D_ (2)补偿收缩混凝土，补偿收缩时≥0.03%_x000D_ (3)满足设计图纸、相关规范、招标文件及技术要求 | D21: m3 | E21: 26.5 | F21: 592.11558 | G21: =+F21*E21 -> 15691.063 | H21: 26.5 | I21: 395.01699 | J21: =+I21*H21 -> 10467.95 | K21: =+人工费!K21 -> 0 | L21: =+R21 -> 592.11558 | M21: =+L21*K21 -> 0 | N21: =+T21-Z21 -> 358 | O21: =+U21 -> 385.72673 | P21: =+V21-AB21 -> 138090.17 | Q21: =+人工费!Q21 -> 26.5 | R21: 592.11558 | S21: =+R21*Q21 -> 15691.063 | T21: 358 | U21: 385.72673 | V21: =+U21*T21 -> 138090.17 | W21: 商砼C40 | AB21: 0
A22: 1.15 | B22: 后浇带 梁、楼板、墙 C40P6 | C22: (1)混凝土强度等级:C40泵送商品混凝土,P6_x000D_ (2)补偿收缩混凝土，补偿收缩时≥0.03%_x000D_ (3)满足设计图纸、相关规范、招标文件及技术要求 | D22: m3 | E22: 90.52 | F22: 590.5032 | G22: =+F22*E22 -> 53452.349 | H22: 90.52 | I22: 393.75485 | J22: =+I22*H22 -> 35642.689 | K22: =+人工费!K22 -> 0 | L22: =+R22 -> 590.5032 | M22: =+L22*K22 -> 0 | N22: =+T22-Z22 -> 149 | O22: =+U22 -> 412.42718 | P22: =+V22-AB22 -> 61451.65 | Q22: =+人工费!Q22 -> 90.52 | R22: 590.5032 | S22: =+R22*Q22 -> 53452.349 | T22: 149 | U22: 412.42718 | V22: =+U22*T22 -> 61451.65 | W22: C40+8%膨胀剂 | AB22: 0
A23: 1.16 | B23: 后浇带 梁、楼板、墙 C60P6 | C23: (1)混凝土强度等级:C60泵送商品混凝土,P6_x000D_ (2)补偿收缩混凝土，补偿收缩时≥0.03%_x000D_ (3)满足设计图纸、相关规范、招标文件及技术要求 | D23: m3 | E23: 86.71 | F23: 673.40829 | G23: =+F23*E23 -> 58391.233 | H23: 86.71 | I23: 452.1034 | J23: =+I23*H23 -> 39201.886 | K23: =+人工费!K23 -> 0 | L23: =+R23 -> 673.40829 | M23: =+L23*K23 -> 0 | N23: =+T23-Z23 -> 0 | O23: =+U23 -> 0 | P23: =+V23-AB23 -> 0 | Q23: =+人工费!Q23 -> 86.71 | R23: 673.40829 | S23: =+R23*Q23 -> 58391.233 | T23: 0 | U23: 0 | V23: =+U23*T23 -> 0 | W23: C40 P6补偿收缩时≥0.03% | AB23: 0
A24: 1.17 | B24: 后浇带 梁、楼板、墙 C40 | C24: (1)混凝土强度等级:C40泵送商品混凝土_x000D_ (2)满足设计图纸、相关规范、招标文件及技术要求 | D24: m3 | E24: 109.07 | F24: 563.74707 | G24: =+F24*E24 -> 61487.893 | H24: 109.07 | I24: 388.70631 | J24: =+I24*H24 -> 42396.197 | K24: =+人工费!K24 -> 0 | L24: =+R24 -> 563.74707 | M24: =+L24*K24 -> 0 | N24: =+T24-Z24 -> 81 | O24: =+U24 -> 418.25247 | P24: =+V24-AB24 -> 33878.45 | Q24: =+人工费!Q24 -> 109.07 | R24: 563.74707 | S24: =+R24*Q24 -> 61487.893 | T24: 81 | U24: 418.25247 | V24: =+U24*T24 -> 33878.45 | W24: C40 P8+8%膨胀剂 | AB24: 0
A25: 1.18 | B25: 直形楼梯 C35 | C25: (1)混凝土强度等级:C35泵送商品混凝土_x000D_ (2)满足设计图纸、相关规范、招标文件及技术要求 | D25: m3 | E25: 25.9 | F25: 545.58402 | G25: =+F25*E25 -> 14130.626 | H25: 25.9 | I25: 381.06408 | J25: =+I25*H25 -> 9869.5596 | K25: =+人工费!K25 -> 0 | L25: =+R25 -> 545.58402 | M25: =+L25*K25 -> 0 | N25: =+T25-Z25 -> 180 | O25: =+U25 -> 417.22333 | P25: =+V25-AB25 -> 75100.2 | Q25: =+人工费!Q25 -> 26.01 | R25: 545.58402 | S25: =+R25*Q25 -> 14190.64 | T25: 180 | U25: 417.22333 | V25: =+U25*T25 -> 75100.2 | W25: C40 P10+8%膨胀剂 | AB25: 0
A26: 1.19 | B26: 构造柱 C20 | C26: (1)混凝土强度等级:C20非泵送商品混凝土_x000D_ (2)满足设计图纸、相关规范、招标文件及技术要求 | D26: m3 | E26: 60.5 | F26: 475.57801 | G26: =+F26*E26 -> 28772.47 | H26: 60.5 | I26: 332.50971 | J26: =+I26*H26 -> 20116.837 | K26: =+人工费!K26 -> 0 | L26: =+R26 -> 475.57801 | M26: =+L26*K26 -> 0 | N26: =+T26-Z26 -> -128.5 | O26: =+U26 -> 431.53402 | P26: =+N26*O26 -> -55452.121 | Q26: =+人工费!Q26 -> 0 | R26: 475.57801 | S26: =+R26*Q26 -> 0 | T26: 117 | U26: 431.53402 | V26: =+U26*T26 -> 50489.48 | W26: 商砼C45 | Z26: 245.5 | AA26: 338.44872 | AB26: 83089.16
A27: 1.2 | B27: 圈、过梁 C20 | C27: (1)混凝土强度等级:C20非泵送商品混凝土_x000D_ (2)满足设计图纸、相关规范、招标文件及技术要求 | D27: m3 | E27: 16.98 | F27: 474.67697 | G27: =+F27*E27 -> 8060.015 | H27: 16.98 | I27: 332.50971 | J27: =+I27*H27 -> 5646.0149 | K27: =+人工费!K27 -> 0 | L27: =+R27 -> 474.67697 | M27: =+L27*K27 -> 0 | N27: =+T27-Z27 -> 1178 | O27: =+U27 -> 431.53395 | P27: =+V27-AB27 -> 508579.31 | Q27: =+人工费!Q27 -> 0 | R27: 474.67697 | S27: =+R27*Q27 -> 0 | T27: 1181 | U27: 431.53395 | V27: =+U27*T27 -> 509641.6 | W27: 商砼C50 | Z27: 3 | AA27: 354.09667 | AB27: 1062.29
A28: 1.21 | B28: 门槛、反坎 C25 | C28: (1)混凝土强度等级:C25非泵送商品混凝土_x000D_ (2)满足设计图纸、相关规范、招标文件及技术要求 | D28: m3 | E28: 10 | F28: 493.94973 | G28: =+F28*E28 -> 4939.4973 | H28: 10 | I28: 346.75291 | J28: =+I28*H28 -> 3467.5291 | K28: =+人工费!K28 -> 0 | L28: =+R28 -> 493.94973 | M28: =+L28*K28 -> 0 | N28: =+T28-Z28 -> 1168.5 | O28: =+U28 -> 442.21734 | P28: =+N28*O28 -> 516730.96 | Q28: =+人工费!Q28 -> 0 | R28: 493.94973 | S28: =+R28*Q28 -> 0 | T28: 1205 | U28: 442.21734 | V28: =+U28*T28 -> 532871.89 | W28: 商砼C55 | Z28: 36.5 | AA28: 358.37068 | AB28: 13080.53
A29: 1.22 | B29: 门槛、反坎 C20 | C29: (1)混凝土强度等级:C20非泵送商品混凝土_x000D_ (2)满足设计图纸、相关规范、招标文件及技术要求 | D29: m3 | E29: 108.25 | F29: 474.32604 | G29: =+F29*E29 -> 51345.794 | H29: 108.25 | I29: 332.50971 | J29: =+I29*H29 -> 35994.176 | K29: =+人工费!K29 -> 0 | L29: =+R29 -> 474.32604 | M29: =+L29*K29 -> 0 | N29: =+T29-Z29 -> 3015 | O29: =+U29 -> 449.36519 | P29: =+V29-AB29 -> 1354836 | Q29: =+人工费!Q29 -> 0 | R29: 474.32604 | S29: =+R29*Q29 -> 0 | T29: 3015 | U29: 449.36519 | V29: =+U29*T29 -> 1354836 | W29: C60 | AB29: 0
A30: 1.23 | B30: 设备基础 C35 | C30: (1)混凝土强度等级:C35非泵送商品混凝土_x000D_ (2)满足设计图纸、相关规范、招标文件及技术要求 | D30: m3 | E30: 31.09 | F30: 554.03482 | G30: =+F30*E30 -> 17224.942 | H30: 31.09 | I30: 381.06408 | J30: =+I30*H30 -> 11847.282 | K30: =+人工费!K30 -> 0 | L30: =+R30 -> 554.03482 | M30: =+L30*K30 -> 0 | N30: =+T30-Z30 -> 0 | O30: =+U30 -> 338.44872 | P30: =+V30-AB30 -> 0 | Q30: =+人工费!Q30 -> 31.09 | R30: 554.03482 | S30: =+R30*Q30 -> 17224.942 | T30: 0 | U30: 338.44872 | V30: =+U30*T30 -> 0 | W30: C60 P6 补偿收缩时≥0.03% | AB30: 0
A31: 1.24 | B31: C20素混凝土（坡道位置）_x000D_ | C31: (1)C20素混凝土_x000D_ (2)满足设计图纸、相关规范、招标文件及技术要求 | D31: m3 | E31: 44.04 | F31: 473.52933 | G31: =+F31*E31 -> 20854.232 | H31: 44.04 | I31: 332.50971 | J31: =+I31*H31 -> 14643.728 | K31: =+人工费!K31 -> 0 | L31: =+R31 -> 473.52933 | M31: =+L31*K31 -> 0 | P31: =+V31-AB31 -> 0 | Q31: =+人工费!Q31 -> 0 | R31: 473.52933 | S31: =+R31*Q31 -> 0 | T31: 32 | V31: =+U31*T31 -> 0 | W31: 润管砂浆 | AB31: 0
A32: 1.25 | B32: 混凝土泵送费扣减 | D32: 项 | E32: 1 | F32: 0 | G32: =+F32*E32 -> 0 | H32: 1 | J32: =+I32*H32 -> 0 | K32: =+人工费!K32 -> 0 | M32: =+L32*K32 -> 0 | P32: =+V32-AB32 -> 0 | Q32: =+人工费!Q32 -> 0 | R32: 0 | S32: =+R32*Q32 -> 0 | V32: =+U32*T32 -> 0 | AB32: 0
A33: 2 | B33: 钢筋工程 | E33: 0 | F33: 0 | G33: =SUM(G34:G61) -> 5997238.7 | H33: 0 | J33: =SUM(J34:J61) -> 5163146.4 | K33: =SUM(K34:K58) -> -50 | M33: =SUM(M34:M61) -> -203714.54 | N33: =SUM(N34:N58) -> 366.71841 | P33: =SUM(P34:P61) -> 1481626.6 | Q33: =SUM(Q34:Q58) -> 1412.575 | S33: =SUM(S34:S61) -> 5746722.2 | T33: =SUM(T34:T58) -> 2324.6994 | V33: =SUM(V34:V61) -> 9343089.8 | Z33: 1957.981 | AB33: 7039825
A34: 2.1 | B34: 现浇构件钢筋 | C34: (1)钢筋种类、规格:拉结筋制安(HPB300)φ6mm_x000D_ (2)满足设计图纸、相关规范、招标文件及技术要求 | D34: t | E34: 4.5 | F34: 4046.482 | G34: =+F34*E34 -> 18209.169 | H34: 4.5 | I34: 3690.4779 | J34: =+I34*H34 -> 16607.15 | K34: =+人工费!K34 -> 0 | L34: =+R34 -> 4046.482 | M34: =+L34*K34 -> 0 | P34: =+N34*O34 -> 0 | Q34: =+人工费!Q34 -> 0 | R34: 4046.482 | S34: =+R34*Q34 -> 0 | V34: 0 | AB34: 0
A35: 2.2 | B35: 现浇构件钢筋 | C35: (1)钢筋种类、规格:圆钢制安 φ6mm_x000D_ (2)满足设计图纸、相关规范、招标文件及技术要求 | D35: t | E35: 0.2 | F35: 4017.0133 | G35: =+F35*E35 -> 803.40265 | H35: 0.2 | I35: 4116.7226 | J35: =+I35*H35 -> 823.34452 | K35: =+人工费!K35 -> 0 | L35: =+R35 -> 4017.0133 | M35: =+L35*K35 -> 0 | P35: =+N35*O35 -> 0 | Q35: =+人工费!Q35 -> 0 | R35: 4017.0133 | S35: =+R35*Q35 -> 0 | V35: 0 | AB35: 0
A36: 2.3 | B36: 现浇构件钢筋 | C36: (1)钢筋种类、规格:圆钢制安 φ8~10mm以上_x000D_ (2)满足设计图纸、相关规范、招标文件及技术要求 | D36: t | E36: 0.2 | F36: 4046.1785 | G36: =+F36*E36 -> 809.23569 | H36: 0.2 | I36: 3646.2301 | J36: =+I36*H36 -> 729.24602 | K36: =+人工费!K36 -> 0 | L36: =+R36 -> 4046.1785 | M36: =+L36*K36 -> 0 | N36: =+T36-Z36 -> 0 | O36: =+U36 -> 0 | P36: =+N36*O36 -> 0 | Q36: =+人工费!Q36 -> 0 | R36: 4046.1785 | S36: =+R36*Q36 -> 0 | V36: 0 | AB36: 0
A37: 2.4 | B37: 现浇构件钢筋 | C37: (1)钢筋种类、规格:螺纹钢制安Ⅲ级(HRB400E)φ6mm (2)满足设计图纸、相关规范、招标文件及技术要求 | D37: t | E37: 0.022 | F37: 4202.6179 | G37: =+F37*E37 -> 92.457593 | H37: 0.022 | I37: 3839.4425 | J37: =+I37*H37 -> 84.467735 | K37: =+人工费!K37 -> 0 | L37: =+R37 -> 4202.6179 | M37: =+L37*K37 -> 0 | N37: =+T37-Z37 -> 5.583981 | O37: =+U37 -> 4334.1068 | P37: =+N37*O37 -> 24201.57 | Q37: =+人工费!Q37 -> 0 | R37: 4202.6179 | S37: =+R37*Q37 -> 0 | T37: 16.693981 | U37: 4334.1068 | V37: =+T37*U37 -> 72353.496 | Z37: 11.11 | AA37: 3957.5666 | AB37: 43968.565
A38: 2.5 | B38: 现浇构件钢筋 | C38: (1)钢筋种类、规格:螺纹钢制安Ⅲ级(HRB400E)φ8mm_x000D_ (2)满足设计图纸、相关规范、招标文件及技术要求 | D38: t | E38: 36.245 | F38: 4002.0465 | G38: =+F38*E38 -> 145054.18 | H38: 36.245 | I38: 3582.8053 | J38: =+I38*H38 -> 129858.78 | K38: =+人工费!K38 -> 0 | L38: =+R38 -> 4002.0465 | M38: =+L38*K38 -> 0 | N38: =+T38-Z38 -> 136.28158 | O38: =+U38 -> 4104.76 | P38: =+N38*O38 -> 559403.18 | Q38: =+人工费!Q38 -> 36.245 | R38: 4002.0465 | S38: =+R38*Q38 -> 145054.18 | T38: 327.65558 | U38: 4104.76 | V38: =+T38*U38 -> 1344947.5 | Z38: 191.374 | AA38: 3718.3741 | AB38: 711600.13
A39: 2.6 | B39: 现浇构件钢筋 | C39: (1)钢筋种类、规格:螺纹钢制安Ⅲ级(HRB400E)φ10mm_x000D_ (2)满足设计图纸、相关规范、招标文件及技术要求 | D39: t | E39: 177.258 | F39: 4059.5518 | G39: =+F39*E39 -> 719588.03 | H39: 177.258 | I39: 3580.1504 | J39: =+I39*H39 -> 634610.31 | K39: =+人工费!K39 -> 0 | L39: =+R39 -> 4059.5518 | M39: =+L39*K39 -> 0 | N39: =+T39-Z39 -> 52.207774 | O39: =+U39 -> 4101.5511 | P39: =+N39*O39 -> 214132.85 | Q39: =+人工费!Q39 -> 177.258 | R39: 4059.5518 | S39: =+R39*Q39 -> 719588.03 | T39: 335.44277 | U39: 4101.5511 | V39: =+T39*U39 -> 1375835.7 | Z39: 283.235 | AA39: 3690.0844 | AB39: 1045161
A40: 2.7 | B40: 现浇构件钢筋 | C40: (1)钢筋种类、规格:螺纹钢制安Ⅲ级(HRB400E)φ12mm_x000D_ (2)满足设计图纸、相关规范、招标文件及技术要求 | D40: t | E40: 313.589 | F40: 4074.2909 | G40: =+F40*E40 -> 1277652.8 | H40: 313.589 | I40: 3518.3274 | J40: =+I40*H40 -> 1103308.8 | K40: =+人工费!K40 -> -50 | L40: =+R40 -> 4074.2909 | M40: =+L40*K40 -> -203714.54 | N40: =+T40-Z40 -> 61.635709 | O40: =+U40 -> 3953.7448 | P40: =+N40*O40 -> 243691.86 | Q40: =+人工费!Q40 -> 263.589 | R40: 4074.2909 | S40: =+R40*Q40 -> 1073938.3 | T40: 435.25071 | U40: 3953.7448 | V40: =+T40*U40 -> 1720870.2 | Z40: 373.615 | AA40: 3544.7996 | AB40: 1324390.3
...

Sheet 机械费
A1: 工程项目机械费计算表
A2: 工程名称： XXX项目
A3: 序号 | B3: 机械名称及型号 | C3: 单位 | D3: 预测工程竣工数据统计 | J3: 本期数据统计 | Q3: 累计数据统计 | X3: 备注 | AA3: 上次累计数据统计
D4: 预算收入 | G4: 计划成本 | J4: 预算收入 | M4: 实际成本 | Q4: 预算收入 | T4: 实际成本 | AA4: 预算收入 | AD4: 实际成本
D5: 工程量 | E5: 单价 | F5: 合价 | G5: 工程量 | H5: 单价 | I5: 合计 | J5: 工程量 | K5: 单价 | L5: 合价 | M5: 工程量 | N5: 天数 | O5: 单价 | P5: 合价 | Q5: 工程量 | R5: 单价 | S5: 合价 | T5: 工程量 | U5: 天数 | V5: 单价 | W5: 合价 | AA5: 工程量 | AB5: 单价 | AC5: 合价 | AD5: 工程量 | AE5: 天数 | AF5: 单价 | AG5: 合价
A6: 一 | B6: 塔吊 | F6: 1807634.2 | I6: 2311838.8 | L6: =SUM(L7:L14) -> 106842.51 | P6: =SUM(P7:P14) -> 141000 | S6: =SUM(S7:S14) -> 1009698.5 | W6: =SUM(W7:W14) -> 1273187.6 | AC6: 902855.95 | AG6: 1351787.6
A7: 1 | B7: 塔吊7020 | C7: 元 | F7: 1495795.2 | I7: 1048800 | J7: =+Q7-AA7 -> 2 | K7: =+R7 -> 53421.257 | L7: =K7*J7 -> 106842.51 | M7: =+T7 -> 1 | N7: =+U7-AE7 -> 2 | O7: =+V7 -> 34500 | P7: =+O7*N7*M7 -> 69000 | Q7: =+U7 -> 14.2 | R7: =F7/2/14 -> 53421.257 | S7: =+R7*Q7 -> 758581.85 | T7: 1 | U7: =2.23+1.17+2+2+2+2.8+2 -> 14.2 | V7: 34500 | W7: =+V7*U7*T7 -> 489900 | AA7: 12.2 | AB7: 53421.257 | AC7: 651739.34 | AD7: 1 | AE7: 12.2 | AF7: 34500 | AG7: 420900
A8: 2 | B8: 塔吊司机 | C8: 元 | F8: 0 | I8: 504000 | L8: =K8*J8 -> 0 | M8: =+T8 -> 1 | N8: =+U8-AE8 -> 2 | O8: =+V8 -> 18000 | P8: =+O8*N8*M8 -> 36000 | S8: =+R8*Q8 -> 0 | T8: 1 | U8: =+U7 -> 14.2 | V8: 18000 | W8: =+V8*U8*T8 -> 255600 | AC8: 0 | AD8: 1 | AE8: 12.2 | AF8: 18000 | AG8: 219600
A9: 3 | B9: 塔吊指挥 | C9: 元 | F9: 0 | I9: 504000 | L9: =K9*J9 -> 0 | M9: =+T9 -> 1 | N9: =+U9-AE9 -> 2 | O9: =+V9 -> 18000 | P9: =+O9*N9*M9 -> 36000 | S9: =+R9*Q9 -> 0 | T9: 1 | U9: =+U7 -> 14.2 | V9: 18000 | W9: =+V9*U9*T9 -> 255600 | AC9: 0 | AD9: 2 | AE9: 12.2 | AF9: 18000 | AG9: 439200
A10: 4 | B10: 塔吊7020进出场及安拆费 | C10: 元 | F10: 121444.82 | I10: 124000 | J10: =+Q10-AA10 -> 0 | K10: =+R10 -> 121444.82 | L10: =K10*J10 -> 0 | M10: =+T10-AD10 -> 0 | N10: / | O10: 62000 | P10: =+O10*M10 -> 0 | Q10: 0.5 | R10: 121444.82 | S10: =+R10*Q10 -> 60722.411 | T10: 1 | U10: / | V10: 62000 | W10: =+V10*T10 -> 62000 | AA10: 0.5 | AB10: 121444.82 | AC10: 60722.411 | AD10: 1 | AE10: / | AF10: 62000 | AG10: 62000
A11: 5 | B11: 塔吊基础混凝土 | C11: 元 | F11: 190394.21 | I11: 81856.768 | J11: =+Q11-AA11 -> 0 | K11: =+R11 -> 190394.21 | L11: =K11*J11 -> 0 | M11: =+T11-AD11 -> 0 | N11: / | O11: 438.05017 | P11: =+O11*M11 -> 0 | Q11: 1 | R11: 190394.21 | S11: =+R11*Q11 -> 190394.21 | T11: 269.5 | U11: / | V11: =+W11/T11 -> 438.05017 | W11: 118054.52 | AA11: 1 | AB11: 190394.21 | AC11: 190394.21 | AD11: 269.5 | AE11: / | AF11: 438.05017 | AG11: 118054.52
A12: 6 | B12: 塔吊基础钢筋 | C12: 元 | I12: 18384 | L12: =K12*J12 -> 0 | M12: =+T12-AD12 -> 0 | N12: / | O12: 3498.7871 | P12: =+O12*M12 -> 0 | S12: =+R12*Q12 -> 0 | T12: 16.489 | U12: / | V12: =+W12/T12 -> 3498.7871 | W12: 57691.5 | AC12: 0 | AD12: 16.489 | AE12: / | AF12: 3498.7871 | AG12: 57691.5
A13: 7 | B13: 塔吊基础混凝土人工 | C13: 元 | I13: 11648 | L13: =K13*J13 -> 0 | M13: =+T13-AD13 -> 0 | N13: / | O13: 48.5 | P13: =+O13*M13 -> 0 | S13: =+R13*Q13 -> 0 | T13: 269.5 | U13: / | V13: 48.5 | W13: =+V13*T13 -> 13070.75 | AC13: 0 | AD13: 269.5 | AE13: / | AF13: 48.5 | AG13: 13070.75
A14: 8 | B14: 塔吊基础钢筋人工 | C14: 元 | I14: 19150 | L14: =K14*J14 -> 0 | M14: =+T14-AD14 -> 0 | N14: / | O14: 1290 | P14: =+O14*M14 -> 0 | S14: =+R14*Q14 -> 0 | T14: 16.489 | U14: / | V14: 1290 | W14: =+V14*T14 -> 21270.81 | AC14: 0 | AD14: 16.489 | AE14: / | AF14: 1290 | AG14: 21270.81
A15: 二 | B15: 施工电梯 | F15: 964650.21 | I15: 1599500.9 | L15: =SUM(L16:L22) -> 0 | P15: =SUM(P16:P22) -> 201672.83 | S15: =SUM(S16:S22) -> 183497.32 | W15: =SUM(W16:W22) -> 201672.83 | AC15: 0 | AG15: 0
A16: 1 | B16: SC200/200、100-150米租赁费 | C16: 元 | F16: 908510.47 | I16: 317500 | L16: =+K16*J16 -> 0 | M16: =+T16 -> 1 | N16: =+U16-AE16 -> 4.2 | O16: =+V16 -> 18000 | P16: =+O16*M16*N16 -> 75600 | Q16: =+U16 -> 4.2 | R16: =F16/12.275/2 -> 37006.537 | S16: =+R16*Q16 -> 155427.45 | T16: 1 | U16: =2.33+1.87 -> 4.2 | V16: 18000 | W16: =+V16*T16*U16 -> 75600 | AC16: 0 | AG16: 0
A17: 2 | B17: 电梯司机 | C17: 元 | I17: 432000 | L17: =+K17*J17 -> 0 | M17: =+T17 -> 1 | N17: =+U17-AE17 -> 4.2 | O17: =+V17 -> 18000 | P17: =+O17*M17*N17 -> 75600 | S17: =+R17*Q17 -> 0 | T17: 1 | U17: =+U16 -> 4.2 | V17: 18000 | W17: =+V17*T17*U17 -> 75600 | AC17: 0 | AG17: 0
A18: 3 | B18: SC200/200、100-150米进出场安拆费用 | C18: 元 | F18: 56139.735 | I18: 838200 | L18: =+K18*J18 -> 0 | M18: =+T18-AD18 -> 1 | N18: / | O18: =+V18 -> 38000 | P18: =+O18*M18 -> 38000 | Q18: 0.5 | R18: =+F18 -> 56139.735 | S18: =+R18*Q18 -> 28069.868 | T18: =0.5+0.5 -> 1 | U18: / | V18: 38000 | W18: =+V18*T18 -> 38000 | AC18: 0 | AG18: 0
A19: 4 | B19: 电梯基础混凝土 | C19: 元 | I19: 8879.9976 | L19: =+K19*J19 -> 0 | M19: =+T19-AD19 -> 32.5 | N19: / | O19: =+V19 -> 335.27938 | P19: =+O19*M19 -> 10896.58 | S19: =+R19*Q19 -> 0 | T19: 32.5 | U19: / | V19: =+W19/T19 -> 335.27938 | W19: 10896.58 | AC19: 0 | AG19: 0
A20: 5 | B20: 电梯基础钢筋 | C20: 元 | I20: 1282.3009 | L20: =+K20*J20 -> 0 | M20: =+T20-AD20 -> 0 | N20: / | O20: =+V20 -> 0 | P20: =+O20*M20 -> 0 | S20: =+R20*Q20 -> 0 | U20: / | W20: =+V20*T20 -> 0 | AC20: 0 | AG20: 0
A21: 6 | B21: 电梯基础混凝土人工 | C21: 元 | I21: 1263.6 | L21: =+K21*J21 -> 0 | M21: =+T21-AD21 -> 32.5 | N21: / | O21: =+V21 -> 48.5 | P21: =+O21*M21 -> 1576.25 | S21: =+R21*Q21 -> 0 | T21: =+T19 -> 32.5 | U21: / | V21: 48.5 | W21: =+V21*T21 -> 1576.25 | AC21: 0 | AG21: 0
A22: 7 | B22: 电梯基础钢筋人工 | C22: 元 | I22: 375 | L22: =+K22*J22 -> 0 | M22: =+T22-AD22 -> 0 | N22: / | O22: =+V22 -> 1290 | P22: =+O22*M22 -> 0 | S22: =+R22*Q22 -> 0 | T22: =+T20 -> 0 | U22: / | V22: 1290 | W22: =+V22*T22 -> 0 | AC22: 0 | AG22: 0
A23: 三 | B23: 泵送费 | C23: 元 | F23: 136065.24 | I23: 451279.3 | J23: =材料费!K286/23296.47 -> 0.044863054 | K23: =+R23 -> 136065.24 | L23: =+S23-AC23 -> 6104.3022 | P23: =+W23-AG23 -> -55376.782 | Q23: =材料费!Q286/23296.47 -> 0.7274476 | R23: 136065.24 | S23: =R23*Q23 -> 98980.33 | W23: =481352.03/1.13 -> 425975.25 | AA23: 0.68258454 | AB23: 136065.24 | AC23: 92876.028 | AG23: 481352.03
A24: 四 | B24: 小型机械费用 | C24: 元 | I24: 135383.79 | L24: =+S24-AC24 -> 0 | P24: =+W24-AG24 -> 0 | S24: =+R24*Q24 -> 0 | W24: =107050+3450 -> 110500 | AC24: 0 | AG24: 110500
A25: 五 | B25: 施工水电费 | C25: 元 | I25: 812302.74 | L25: =+S25-AC25 -> 0 | P25: =+W25-AG25 -> 30483.34 | S25: =+R25*Q25 -> 0 | W25: 211286.91 | AC25: 0 | AG25: 180803.57
B26: 合计 | F26: =+F25+F24+F23+F15+F6 -> 2908349.7 | I26: =+I25+I24+I23+I15+I6 -> 5310305.5 | L26: =+L25+L24+L23+L15+L6 -> 112946.82 | P26: =+P25+P24+P23+P15+P6 -> 317779.39 | S26: =+S25+S24+S23+S15+S6 -> 1292176.1 | W26: =+W25+W24+W23+W15+W6 -> 2222622.6 | AC26: 995731.98 | AG26: 2124443.2

Sheet 专业分包费
A1: 工程项目专业分包费计算表
A2: 工程名称： XXX项目
A3: 序号 | B3: 分部分项名称 | C3: 项目特征 | D3: 单位 | E3: 预测工程竣工数据统计 | K3: 本期数据统计 | Q3: 累计数据统计 | W3: 备注 | Y3: 上次累计数据统计
E4: 预算收入 | H4: 计划成本 | K4: 预算收入 | N4: 实际成本 | Q4: 预算收入 | T4: 实际成本 | Y4: 预算收入 | AB4: 实际成本
E5: 工程量 | F5: 单价 | G5: 合价 | H5: 工程量 | I5: 单价 | J5: 合计 | K5: 工程量 | L5: 单价 | M5: 合价 | N5: 工程量 | O5: 单价 | P5: 合价 | Q5: 工程量 | R5: 单价 | S5: 合价 | T5: 工程量 | U5: 单价 | V5: 合价 | X5: =+X294+X295+X296+X312+X313+X468 -> 1093058.7 | Y5: 工程量 | Z5: 单价 | AA5: 合价 | AB5: 工程量 | AC5: 单价 | AD5: 合价
A6: 一 | B6: 土石方工程 | G6: =SUM(G7:G15) -> 748244.66 | J6: =SUM(J7:J15) -> 414077.95 | M6: =SUM(M7:M15) -> -37489.213 | P6: =SUM(P7:P15) -> -312278.28 | S6: =SUM(S7:S15) -> 2121654.5 | V6: =SUM(V7:V15) -> 1652037.3 | AA6: 2121654.5 | AD6: 1964315.6
A7: 1 | B7: 挖一般土方 | D7: m3 | E7: 2029.36 | F7: 3.3954953 | G7: 6890.6824 | H7: 2029.36 | J7: 20293.6 | K7: =+Q7-Y7 -> 0 | L7: =+R7 -> 3.3954953 | M7: =+L7*K7 -> 0 | N7: =+T7-AB7 -> 0 | O7: =+U7 -> 7 | P7: =+O7*N7 -> 0 | Q7: 12899.8 | R7: 3.3954953 | S7: =+R7*Q7 -> 43801.211 | T7: =+Q7 -> 12899.8 | U7: 7 | V7: =+U7*T7 -> 90298.6 | W7: =_xlfn.DISPIMG("ID_B109C0F5CA4242FF90574D65B8EAB85B",1) -> #NAME? | Y7: 12899.8 | Z7: 3.3954953 | AA7: 43801.211 | AB7: 12899.8 | AC7: 7 | AD7: 90298.6
A8: 2 | B8: 挖基坑土方 | D8: m3 | E8: 449.33 | F8: 8.6784308 | G8: 3899.4793 | H8: 449.33 | J8: 6739.95 | K8: =+Q8-Y8 -> 0 | L8: =+R8 -> 8.6784308 | M8: =+L8*K8 -> 0 | N8: =+T8-AB8 -> -1452.8658 | O8: =+U8 -> 12 | P8: =+O8*N8 -> -17434.389 | Q8: 2197.28 | R8: 8.6784308 | S8: =+R8*Q8 -> 19068.942 | T8: 744.41425 | U8: 12 | V8: =+U8*T8 -> 8932.971 | Y8: 2197.28 | Z8: 8.6784308 | AA8: 19068.942 | AB8: 2197.28 | AC8: 12 | AD8: 26367.36
A9: 3 | B9: 石方破除 | D9: m3 | E9: 299.55 | F9: 104.56798 | G9: 31323.338 | H9: 299.55 | J9: 11982 | K9: =+Q9-Y9 -> 0 | L9: =+R9 -> 104.56798 | M9: =+L9*K9 -> 0 | N9: =+T9-AB9 -> 0 | O9: =+U9 -> 35 | P9: =+O9*N9 -> 0 | Q9: 16.13 | R9: 104.56798 | S9: =+R9*Q9 -> 1686.6815 | T9: 0 | U9: 35 | V9: =+U9*T9 -> 0 | Y9: 16.13 | Z9: 104.56798 | AA9: 1686.6815 | AB9: 0 | AC9: 35 | AD9: 0
A10: 4 | B10: 余方弃置 | D10: m3 | E10: 2778.24 | F10: 137.52705 | G10: 382083.14 | H10: 2778.24 | J10: 375062.4 | K10: =+Q10-Y10 -> 0 | L10: =+R10 -> 137.52705 | M10: =+L10*K10 -> 0 | N10: =+T10-AB10 -> -2070.3658 | O10: =+U10 -> 120 | P10: =+O10*N10 -> -248443.89 | Q10: 15397.08 | R10: 137.52705 | S10: =+R10*Q10 -> 2117514.9 | T10: 13326.714 | U10: 120 | V10: =+U10*T10 -> 1599205.7 | Y10: 15397.08 | Z10: 137.52705 | AA10: 2117514.9 | AB10: 15397.08 | AC10: 120 | AD10: 1847649.6
A11: 5 | B11: 场内取土回填 | D11: m3 | E11: 2478.69 | F11: 19.585748 | G11: 48546.998 | H11: 2478.69 | J11: 0 | K11: =+Q11-Y11 -> 0 | L11: =+R11 -> 19.585748 | M11: =+L11*K11 -> 0 | N11: =+T11-AB11 -> 0 | O11: 0 | P11: =+O11*N11 -> 0 | Q11: 1264.78 | R11: 19.585748 | S11: =+R11*Q11 -> 24771.663 | T11: 0 | U11: 0 | V11: =+U11*T11 -> 0 | Y11: 1264.78 | Z11: 19.585748 | AA11: 24771.663 | AB11: 0 | AC11: 0 | AD11: 0
A12: 6 | B12: 场外取土回填 | D12: m3 | E12: 5907.12 | F12: 55.428142 | G12: 327420.68 | H12: 5907.12 | J12: 0 | K12: =+Q12-Y12 -> 0 | L12: =+R12 -> 55.428142 | M12: =+L12*K12 -> 0 | N12: =+T12-AB12 -> 2320 | O12: -20 | P12: =+O12*N12 -> -46400 | Q12: 0 | R12: 55.428142 | S12: =+R12*Q12 -> 0 | T12: 2320 | U12: -20 | V12: =+U12*T12 -> -46400 | Y12: 0 | Z12: 55.428142 | AA12: 0 | AB12: 0 | AC12: -20 | AD12: 0
A13: 7 | B13: 场外取土回填(群楼、塔楼屋面) | D13: m3 | E13: 150 | F13: 58.339921 | G13: 8750.9882 | H13: 150 | J13: 0 | K13: =+Q13-Y13 -> 0 | L13: =+R13 -> 58.339921 | M13: =+L13*K13 -> 0 | N13: =+T13-AB13 -> 0 | O13: 0 | P13: =+O13*N13 -> 0 | Q13: 0 | R13: 58.339921 | S13: =+R13*Q13 -> 0 | T13: 0 | U13: 0 | V13: =+U13*T13 -> 0 | Y13: 0 | Z13: 58.339921 | AA13: 0 | AB13: 0 | AC13: 0 | AD13: 0
A14: 8 | B14: 管理费 | D14: 项 | E14: 1 | F14: -29515.941 | G14: -29515.941 | H14: 1 | J14: 0 | K14: 1 | L14: =+R14 -> -6334.5 | M14: =+L14*K14 -> -6334.5 | N14: =+T14-AB14 -> 0 | O14: 0 | P14: =+O14*N14 -> 0 | Q14: 1 | R14: -6334.5 | S14: =+R14*Q14 -> -6334.5 | Y14: 1 | Z14: -6334.5 | AA14: -6334.5 | AB14: 0 | AC14: 0 | AD14: 0
A15: 9 | B15: 利润 | D15: 项 | E15: 1 | F15: -31154.713 | G15: -31154.713 | H15: 1 | J15: 0 | K15: 1 | L15: =F15 -> -31154.713 | M15: =+L15*K15 -> -31154.713 | N15: =+T15-AB15 -> 0 | O15: 0 | P15: =+O15*N15 -> 0 | Q15: 1 | R15: -78854.41 | S15: =+R15*Q15 -> -78854.41 | Y15: 1 | Z15: -78854.41 | AA15: -78854.41 | AB15: 0 | AC15: 0 | AD15: 0
A16: 二 | B16: 幕墙工程 | G16: 2682918.9 | J16: 5551864.2 | M16: =SUM(M17:M31) -> -234160.23 | P16: =SUM(P17:P31) -> 0 | S16: =SUM(S17:S31) -> -234160.23 | V16: =SUM(V17:V31) -> 0 | AA16: 0 | AD16: 0
A17: 1 | B17: 铝合金格栅幕墙 | C17: (1)立面铝合金格栅_x000D_ (2)铝合金表面做法:可见部分表面氟碳喷涂，不可见部分采用阳极氧化处理_x000D_ (3)综合单价包括面层、骨架、铝合金挂件、M6铝种钉和不锈钢弹簧垫圈@300mm、结构胶、胶带、阳极氧化角铝等费用综合考虑等所有费用_x000D_ (4)工程量计算规则:按设计图示尺寸以正立面投影面积计算_x000D_ (5)图纸位置;塔楼屋面，裙楼图F4014，F3012，F2001~05-EL(裙房),F3001~03-PE(裙房)_x000D_ (6)满足设计图纸、相关规范、招标文件及技术要求_x000D_ (7)建筑物超高增加费 | D17: m2 | E17: 668.56 | F17: 542.78605 | G17: 362885.04 | H17: 668.56 | J17: 735416 | L17: 542.78605 | M17: =+L17*K17 -> 0 | P17: =+O17*N17 -> 0 | R17: 542.78605 | S17: =+R17*Q17 -> 0 | V17: =+U17*T17 -> 0 | Z17: 542.78605 | AA17: 0 | AD17: 0
A18: 2 | B18: 铝单板幕墙 | C18: (1)2.5mm厚铝单板(氟碳三涂，颜色综合考虑)_x000D_ (2)综合单价包括面层、骨架、连接件等所有费用_x000D_ (3)工程量计算规则:按设计图示尺寸以可见光铝板展开面积计算_x000D_ (4)满足设计图纸、相关规范、招标文件及技术要求_x000D_ (5)建筑物超高增加费 | D18: m2 | E18: 3205.63 | F18: 450.26355 | G18: 1443378.3 | H18: 3205.63 | J18: 3109461.1 | L18: 450.26355 | M18: =+L18*K18 -> 0 | P18: =+O18*N18 -> 0 | R18: 450.26355 | S18: =+R18*Q18 -> 0 | V18: =+U18*T18 -> 0 | Z18: 450.26355 | AA18: 0 | AD18: 0
A19: 3 | B19: 穿孔铝板幕墙一 | C19: (1)4mm厚穿孔铝板(粉末喷涂，颜色综合考虑)_x000D_ (2)综合单价包括面层、骨架、连接件等所有费用_x000D_ (3)工程量计算规则:按设计图示尺寸以可见光铝板展开面积计算_x000D_ (4)满足设计图纸、相关规范、招标文件及技术要求_x000D_ (5)建筑物超高增加费 | D19: m2 | E19: 177.54 | F19: 447.39919 | G19: 79431.253 | H19: 177.54 | J19: 213048 | L19: 447.39919 | M19: =+L19*K19 -> 0 | P19: =+O19*N19 -> 0 | R19: 447.39919 | S19: =+R19*Q19 -> 0 | V19: =+U19*T19 -> 0 | Z19: 447.39919 | AA19: 0 | AD19: 0
A20: 4 | B20: 穿孔铝板幕墙二 | C20: (1)2mm厚穿孔铝板，穿孔率10%(粉末喷涂，颜色综合考虑)_x000D_ (2)综合单价包括面层、骨架、连接件等所有费用_x000D_ (3)满足设计图纸、相关规范、招标文件及技术要求_x000D_ (4)建筑物超高增加费 | D20: m2 | E20: 773.15 | F20: 253.23946 | G20: 195792.09 | H20: 773.15 | J20: 564399.5 | L20: 253.23946 | M20: =+L20*K20 -> 0 | P20: =+O20*N20 -> 0 | R20: 253.23946 | S20: =+R20*Q20 -> 0 | V20: =+U20*T20 -> 0 | Z20: 253.23946 | AA20: 0 | AD20: 0
A21: 5 | B21: 铝合金格栅雨棚 | C21: (1)铝合金型材格栅雨棚_x000D_ (2)铝合金表面做法:可见部分表面氟碳喷涂，不可见部分采用阳极氧化处理_x000D_ (3)综合单价包括面层、骨架、铝合金挂件、M6铝种钉和不锈钢弹簧垫圈@300mm、结构胶、胶带、阳极氧化角铝等费用综合考虑_x000D_ (4)详雨棚图纸F3006,及个节点大样_x000D_ (5)满足设计图纸、相关规范、招标文件及技术要求_x000D_ (6)建筑物超高增加费 | D21: m2 | E21: 86 | F21: 537.6359 | G21: 46236.688 | H21: 86 | J21: 48749.1 | L21: 537.6359 | M21: =+L21*K21 -> 0 | P21: =+O21*N21 -> 0 | R21: 537.6359 | S21: =+R21*Q21 -> 0 | V21: =+U21*T21 -> 0 | Z21: 537.6359 | AA21: 0 | AD21: 0
A22: 6 | B22: 不锈钢水槽 | C22: (1)2mm厚316不锈钢板_x000D_ (2)工程量计算规则:按设计图示尺寸以展开面积计算_x000D_ (3)详雨棚图纸F3006,及个节点大样_x000D_ (4)满足设计图纸、相关规范、招标文件及技术要求_x000D_ (5)建筑物超高增加费 | D22: m2 | E22: 62.87 | F22: 479.12526 | G22: 30122.605 | H22: 62.87 | J22: 31759.409 | L22: 479.12526 | M22: =+L22*K22 -> 0 | P22: =+O22*N22 -> 0 | R22: 479.12526 | S22: =+R22*Q22 -> 0 | V22: =+U22*T22 -> 0 | Z22: 479.12526 | AA22: 0 | AD22: 0
A23: 7 | B23: 铝合金格栅吊顶 | C23: (1)架空层吊顶,铝合金格栅 A15、A16_x000D_ (2)铝合金表面做法:可见部分表面氟碳喷涂，不可见部分采用阳极氧化处理_x000D_ (3)图纸:F1019~1023-PL(吊顶)，大样图F4029_x000D_ (4)钢骨架:100x50x5mm方管, 氟碳喷涂(深色)转接件间距@3000mm；120x60x4mm方管@1200mm, 氟碳喷涂(深色)_x000D_ (5)满足设计图纸、相关规范、招标文件及技术要求_x000D_ (6)建筑物超高增加费 | D23: m2 | E23: 850 | F23: 347.61146 | G23: 295469.74 | H23: 850 | J23: 306000 | L23: 347.61146 | M23: =+L23*K23 -> 0 | P23: =+O23*N23 -> 0 | R23: 347.61146 | S23: =+R23*Q23 -> 0 | V23: =+U23*T23 -> 0 | Z23: 347.61146 | AA23: 0 | AD23: 0
A24: 8 | B24: 石材幕墙 | C24: (1)30mm厚大理石，6面防护处理_x000D_ (2)综合单价包括面层、热镀锌钢骨架、铝合金挂件、石材背栓件、连接件、螺栓、防火隔离带封堵、保温棉、嵌缝塞缝防水、防雷接地、石材加工防护费(石材磨边、倒角、切割、拼接、背筋、六面防水防污防腐、养护等)等除所有费用_x000D_ (3)满足设计图纸、相关规范、招标文件及技术要求_x000D_ (4)建筑物超高增加费 | D24: m2 | E24: 47.68 | F24: 520.29801 | G24: 24807.809 | H24: 47.68 | J24: 61030.4 | L24: 520.29801 | M24: =+L24*K24 -> 0 | P24: =+O24*N24 -> 0 | R24: 520.29801 | S24: =+R24*Q24 -> 0 | V24: =+U24*T24 -> 0 | Z24: 520.29801 | AA24: 0 | AD24: 0
A25: 9 | B25: 铝合金装饰线一 | C25: (1)铝合金装饰线条 A4_x000D_ (2)铝合金表面做法:可见部分表面氟碳喷涂，不可见部分采用阳极氧化处理_x000D_ (3)图纸:大样图F4006_x000D_ (4)M8后扩底锚栓两颗一组@650mm_x000D_ (5)75x50x4mm热镀锌角钢L=110mm@650mm_x000D_ (6)泡沫棒&密封胶_x000D_ (7)满足设计图纸、相关规范、招标文件及技术要求_x000D_ (8)建筑物超高增加费 | D25: m | E25: 120.4 | F25: 76.152045 | G25: 9168.7062 | H25: 120.4 | J25: 9666.916 | L25: 76.152045 | M25: =+L25*K25 -> 0 | P25: =+O25*N25 -> 0 | R25: 76.152045 | S25: =+R25*Q25 -> 0 | V25: =+U25*T25 -> 0 | Z25: 76.152045 | AA25: 0 | AD25: 0
A26: 10 | B26: 铝合金装饰线二 | C26: (1)铝合金装饰线条 A6_x000D_ (2)铝合金表面做法:可见部分表面氟碳喷涂，不可见部分采用阳极氧化处理_x000D_ (3)图纸:大样图F3005_x000D_ (4)满足设计图纸、相关规范、招标文件及技术要求_x000D_ (5)建筑物超高增加费 | D26: m | E26: 54 | F26: 25.902508 | G26: 1398.7354 | H26: 54 | J26: 1474.74 | L26: 25.902508 | M26: =+L26*K26 -> 0 | P26: =+O26*N26 -> 0 | R26: 25.902508 | S26: =+R26*Q26 -> 0 | V26: =+U26*T26 -> 0 | Z26: 25.902508 | AA26: 0 | AD26: 0
A27: 11 | B27: 裙楼首层玻璃幕墙 | C27: (1)玻璃幕墙(含地弹门)_x000D_ (2)断热铝合金+较低透光Low-E中空玻璃6+12A+6，含弧形玻璃_x000D_ (3)铝合金表面做法:可见部分表面氟碳喷涂，不可见部分采用阳极氧化处理_x000D_ (4)含全部五金配件_x000D_ (5)综合单价包括面层、骨架、结构胶、密封胶等费用综合考虑等所有费用_x000D_ (6)工程量计算规则:按设计图示框外围尺寸计算_x000D_ (7)满足设计图纸、相关规范、招标文件及技术要求_x000D_ (8)建筑物超高增加费 | D27: m2 | E27: 321.71 | F27: 929.5785 | G27: 299054.7 | H27: 321.71 | J27: 337152.08 | L27: 929.5785 | M27: =+L27*K27 -> 0 | P27: =+O27*N27 -> 0 | R27: 929.5785 | S27: =+R27*Q27 -> 0 | V27: =+U27*T27 -> 0 | Z27: 929.5785 | AA27: 0 | AD27: 0
A28: 12 | B28: 预埋件 | C28: (1)结构镀锌钢预埋件_x000D_ (2)预埋在主体结构，综合考虑_x000D_ (3)满足设计图纸、相关规范、招标文件及技术要求_x000D_ (4)建筑物超高增加费 | D28: t | E28: 9.723 | F28: 8810.6939 | G28: 85666.377 | H28: 9.723 | J28: 87507 | L28: 8810.6939 | M28: =+L28*K28 -> 0 | P28: =+O28*N28 -> 0 | R28: 8810.6939 | S28: =+R28*Q28 -> 0 | V28: =+U28*T28 -> 0 | Z28: 8810.6939 | AA28: 0 | AD28: 0
A29: 13 | B29: 后置埋件 | C29: (1)后置埋件_x000D_ (2)12mm厚热镀锌钢板300*250mm，M12后扩底不锈钢锚栓_x000D_ (3)因投标单位自身原因(如预埋件埋偏等)增加后置埋件不给予计算工程量_x000D_ (4)满足设计图纸、相关规范、招标文件及技术要求_x000D_ (5)建筑物超高增加费 | D29: 套 | E29: 308 | F29: 141.77616 | G29: 43667.056 | H29: 308 | J29: 46200 | L29: 141.77616 | M29: =+L29*K29 -> 0 | P29: =+O29*N29 -> 0 | R29: 141.77616 | S29: =+R29*Q29 -> 0 | V29: =+U29*T29 -> 0 | Z29: 141.77616 | AA29: 0 | AD29: 0
A30: 14 | B30: 管理费 | D30: 项 | E30: 1 | F30: -95274.299 | G30: -95274.299 | H30: 1 | J30: 0 | K30: 1 | L30: -95274.299 | M30: =+L30*K30 -> -95274.299 | P30: =+O30*N30 -> 0 | Q30: 1 | R30: -95274.299 | S30: =+R30*Q30 -> -95274.299 | V30: =+U30*T30 -> 0 | Z30: -95274.299 | AA30: 0 | AD30: 0
A31: 15 | B31: 利润 | D31: 项 | E31: 1 | F31: -138885.93 | G31: -138885.93 | H31: 1 | J31: 0 | K31: 1 | L31: -138885.93 | M31: =+L31*K31 -> -138885.93 | P31: =+O31*N31 -> 0 | Q31: 1 | R31: -138885.93 | S31: =+R31*Q31 -> -138885.93 | V31: =+U31*T31 -> 0 | Z31: -138885.93 | AA31: 0 | AD31: 0
A32: 三 | B32: 门窗工程 | G32: 6371514.5 | J32: 7029195.8 | M32: =+M33+M60+M96+M131 -> -13057.7 | P32: =+P33+P60+P96+P131 -> 0 | S32: =+S33+S60+S96+S131 -> -13057.7 | V32: =+V33+V60+V96+V131 -> 0 | AA32: 0 | AD32: 0
A33: 1 | B33: 地下室 | F33: 0 | M33: =+M34+M39+M44+M47+M50+M58+M59 -> -13057.7 | P33: =+P34+P39+P44+P47+P50+P58+P59 -> 0 | R33: 0 | S33: =+S34+S39+S44+S47+S50+S58+S59 -> -13057.7 | V33: =+V34+V39+V44+V47+V50+V58+V59 -> 0 | Z33: 0 | AA33: 0 | AD33: 0
A34: 1.1 | B34: 甲级防火门 | F34: 0 | M34: =SUM(M35:M38) -> 0 | P34: =SUM(P35:P38) -> 0 | R34: 0 | S34: =SUM(S35:S38) -> 0 | V34: =SUM(V35:V38) -> 0 | Z34: 0 | AA34: 0 | AD34: 0
A35: 1.1.1 | B35: 钢质防火门 | C35: (1)甲级钢质防火门，FM甲0619_x000D_ (2)尺寸：600x1900_x000D_ (3)含控制箱、闭门器、顺序器等全部不锈钢五金配件安装_x000D_ (4)前室、合用前室以及楼梯间的防火门须带视口_x000D_ (5)满足设计图纸、相关规范、招标文件及技术要求 | D35: 樘 | E35: 1 | F35: 543.9906 | G35: 543.9906 | H35: 1 | J35: 535.8 | L35: 543.9906 | M35: =+L35*K35 -> 0 | P35: =+O35*N35 -> 0 | R35: 543.9906 | S35: =+R35*Q35 -> 0 | V35: =+U35*T35 -> 0 | Z35: 543.9906 | AA35: 0 | AD35: 0
